Workbook

Sheet Listas
A1: FechasPRE | B1: FechasPOST | C1: SiNo | D1: EstadoCita | E1: Categoria | F1: CanalPRE | G1: Sexo | H1: EstadoPaciente | I1: ResultadoVI
A2: 46237 | B2: 46267 | C2: Sí | D2: Asistió | E2: Citas | F2: Presencial | G2: M | H2: Activo | I2: Implementado
A3: 46239 | B3: 46269 | C3: No | D3: No asistió | E3: Horarios | F3: Telefónico | G3: F | H3: Inactivo | I3: No implementado
A4: 46241 | B4: 46272 | D4: Cancelada | E4: Información institucional | F4: WhatsApp institucional
A5: 46244 | B5: 46274 | D5: Reprogramada | E5: Requisitos
A6: 46246 | B6: 46276 | E6: Ubicación
A7: 46248 | B7: 46279 | E7: Seguimiento administrativo
A8: 46251 | B8: 46281 | E8: Otro
A9: 46253 | B9: 46283
A10: 46255 | B10: 46286
A11: 46258 | B11: 46288
A12: 46260 | B12: 46290
A13: 46262 | B13: 46293
A14: 46265 | B14: 46295

Sheet Configuracion
A1: CONFIGURACIÓN DEL ESTUDIO
A2: Código de estudio: | B2: SWC-FO-2026 (Sistema Web con Chatbot - Fundación Oncológica - 2026)
A3: Título: | B3: Sistema web con chatbot para la gestión de pacientes en una fundación oncológica privada de Lima, 2026
A4: Diseño: | B4: Pre-experimental de un solo grupo, con pretest y postest, comparados mediante 13 sesiones equivalentes
A5: Fechas PRETEST (lun/mié/vie): | B5: 03/08/2026, 05/08/2026, 07/08/2026, 10/08/2026, 12/08/2026, 14/08/2026, 17/08/2026, 19/08/2026, 21/08/2026, 24/08/2026, 26/08/2026, 28/08/2026, 31/08/2026
A6: Fechas POSTEST (lun/mié/vie): | B6: 02/09/2026, 04/09/2026, 07/09/2026, 09/09/2026, 11/09/2026, 14/09/2026, 16/09/2026, 18/09/2026, 21/09/2026, 23/09/2026, 25/09/2026, 28/09/2026, 30/09/2026
A7: Unidad de análisis - TPR: | B7: Cada proceso de registro de paciente efectivamente ejecutado
A8: Unidad de análisis - Ausentismo: | B8: Cada cita médica programada elegible (se excluyen citas canceladas o reprogramadas con anticipación)
A9: Unidad de análisis - Consultas: | B9: Cada consulta administrativa recibida (canales habituales en el pretest; chatbot en el postest)
A10: Fórmula TPR: | B10: TPR = (Σ tiempo de cada registro) / (N.° de registros), en minutos
A11: Fórmula Tasa de Ausentismo: | B11: TA = (N.° de citas no asistidas sin previo aviso / N.° de citas programadas elegibles) x 100
A12: Fórmula Nivel de Consultas Atendidas: | B12: NCA = (N.° de consultas resueltas en el primer contacto y no derivadas / N.° de consultas recibidas) x 100
A13: Criterios de inclusión: | B13: Pacientes activos de la fundación oncológica durante el período de estudio, mayores de edad, con al menos una cita programada en la institución en dicho período y que acepten participar mediante consentimiento informado.
... A15: Regla de calidad de datos: | B15: Registrar únicamente los eventos que realmente ocurrieron cada sesión. No completar filas artificiales para alcanzar un número fijo de registros, citas o consultas.
A17: CÓMO USAR ESTE ARCHIVO
A18: 1. Use la hoja Pacientes para registrar a los 30 participantes (código, edad, sexo). Si aparece un paciente nuevo durante el postest que no estaba en la lista original, agréguelo al final.
A19: 2. En cada hoja PRE/POST (TPR, Ausentismo, Consultas), agregue una fila por cada evento real (registro, cita o consulta) que haya ocurrido, seleccionando la fecha de la lista desplegable. No es necesario llenar un número fijo de filas por sesión.
A20: 3. Las celdas en amarillo son las que debe completar con datos reales. Las columnas de fecha y las categóricas tienen lista desplegable para evitar errores de escritura.
A21: 4. La hoja Sesiones calcula automáticamente el valor de cada indicador por sesión (13 PRE y 13 POST) a partir de lo que usted haya registrado. No edite esa hoja manualmente.
A22: 5. La hoja Resumen_PRE_POST muestra el promedio general de cada indicador; se actualiza sola.
A24: REGLAS DE REGISTRO (versión 3)
A25: Consulta resuelta: | B25: Se marca "Sí" en la columna F solo si el paciente obtuvo la información solicitada en el primer contacto y no necesitó volver a comunicarse por el mismo motivo. Se aplica igual en el pretest y en el postest.
A26: Consulta derivada: | B26: Se marca "Sí" en la columna G si la consulta tuvo que pasarse a otra persona o área para completarse. Una consulta derivada no cuenta como resuelta para el NCA.
A27: Aviso previo (ausentismo): | B27: Si el paciente avisó antes de la fecha, la cita se registra como "Cancelada" o "Reprogramada" y no entra al cálculo. "No asistió" se usa solo para inasistencias sin aviso.
A28: Sesiones sin eventos: | B28: Si una sesión no tiene eventos de un indicador, su valor queda vacío y el par se marca como no válido en la hoja Sesiones; se excluye del contraste y se informa el número de pares válidos.
A29: Emparejamiento de sesiones: | B29: Por día de la semana y orden de aparición (1.er lunes PRE con 1.er lunes POST, etc.). Pares 1 a 12 con el mismo día; el par 13 une las últimas sesiones (lun 31/08 – mié 30/09) y se excluye en el análisis de sensibilidad. Ver columna S de la hoja Sesiones.
A30: Variable independiente: | B30: Registrar en la hoja Verificacion_VI la verificación de cada módulo del sistema antes de iniciar el postest.
A31: Control de calidad: | B31: Columna "Control de calidad" en cada hoja de registro y resumen en la hoja Control_Calidad. Consentimientos y bitácora en sus hojas respectivas.
A32: Exportación a SPSS: | B32: La hoja SPSS_Pares arma automáticamente los 13 pares para el archivo Analisis_SPSS.sps.

Sheet Pacientes
A1: Código | B1: Edad | C1: Sexo | D1: Estado | E1: Participó en la muestra original (30)
A2: PAC-01 | E2: Sí
A3: PAC-02 | E3: Sí
A4: PAC-03 | E4: Sí
A5: PAC-04 | E5: Sí
A6: PAC-05 | E6: Sí
A7: PAC-06 | E7: Sí
A8: PAC-07 | E8: Sí
A9: PAC-08 | E9: Sí
A10: PAC-09 | E10: Sí
A11: PAC-10 | E11: Sí
A12: PAC-11 | E12: Sí
A13: PAC-12 | E13: Sí
... A31: PAC-30 | E31: Sí
E32: No (nuevo)
E33: No (nuevo)
E34: No (nuevo)
E35: No (nuevo)
E36: No (nuevo)
E37: No (nuevo)
E38: No (nuevo)
E39: No (nuevo)
E40: No (nuevo)
E41: No (nuevo)
E42: No (nuevo)
E43: No (nuevo)
... E46: No (nuevo)

Sheet Consentimientos
A1: Código del paciente | B1: Firmó el consentimiento | C1: Fecha de firma | D1: Retiró su consentimiento | E1: Fecha de retiro | F1: Observación | G1: Control
A2: =IF(Pacientes!A2="","",Pacientes!A2) | G2: =IF(A2="","",IF(B2<>"Sí","Sin consentimiento: excluir sus registros",IF(C2="","Falta fecha de firma",IF(C2>DATE(2026,8,3),"Firmado después del inicio del pretest (declarar)",IF(D2="Sí","Retirado: excluir desde la fecha de retiro","OK")))))
A3: =IF(Pacientes!A3="","",Pacientes!A3) | G3: =IF(A3="","",IF(B3<>"Sí","Sin consentimiento: excluir sus registros",IF(C3="","Falta fecha de firma",IF(C3>DATE(2026,8,3),"Firmado después del inicio del pretest (declarar)",IF(D3="Sí","Retirado: excluir desde la fecha de retiro","OK")))))
A4: =IF(Pacientes!A4="","",Pacientes!A4) | G4: =IF(A4="","",IF(B4<>"Sí","Sin consentimiento: excluir sus registros",IF(C4="","Falta fecha de firma",IF(C4>DATE(2026,8,3),"Firmado después del inicio del pretest (declarar)",IF(D4="Sí","Retirado: excluir desde la fecha de retiro","OK")))))
A5: =IF(Pacientes!A5="","",Pacientes!A5) | G5: =IF(A5="","",IF(B5<>"Sí","Sin consentimiento: excluir sus registros",IF(C5="","Falta fecha de firma",IF(C5>DATE(2026,8,3),"Firmado después del inicio del pretest (declarar)",IF(D5="Sí","Retirado: excluir desde la fecha de retiro","OK")))))
A6: =IF(Pacientes!A6="","",Pacientes!A6) | G6: =IF(A6="","",IF(B6<>"Sí","Sin consentimiento: excluir sus registros",IF(C6="","Falta fecha de firma",IF(C6>DATE(2026,8,3),"Firmado después del inicio del pretest (declarar)",IF(D6="Sí","Retirado: excluir desde la fecha de retiro","OK")))))
A7: =IF(Pacientes!A7="","",Pacientes!A7) | G7: =IF(A7="","",IF(B7<>"Sí","Sin consentimiento: excluir sus registros",IF(C7="","Falta fecha de firma",IF(C7>DATE(2026,8,3),"Firmado después del inicio del pretest (declarar)",IF(D7="Sí","Retirado: excluir desde la fecha de retiro","OK")))))
A8: =IF(Pacientes!A8="","",Pacientes!A8) | G8: =IF(A8="","",IF(B8<>"Sí","Sin consentimiento: excluir sus registros",IF(C8="","Falta fecha de firma",IF(C8>DATE(2026,8,3),"Firmado después del inicio del pretest (declarar)",IF(D8="Sí","Retirado: excluir desde la fecha de retiro","OK")))))
A9: =IF(Pacientes!A9="","",Pacientes!A9) | G9: =IF(A9="","",IF(B9<>"Sí","Sin consentimiento: excluir sus registros",IF(C9="","Falta fecha de firma",IF(C9>DATE(2026,8,3),"Firmado después del inicio del pretest (declarar)",IF(D9="Sí","Retirado: excluir desde la fecha de retiro","OK")))))
A10: =IF(Pacientes!A10="","",Pacientes!A10) | G10: =IF(A10="","",IF(B10<>"Sí","Sin consentimiento: excluir sus registros",IF(C10="","Falta fecha de firma",IF(C10>DATE(2026,8,3),"Firmado después del inicio del pretest (declarar)",IF(D10="Sí","Retirado: excluir desde la fecha de retiro","OK")))))
A11: =IF(Pacientes!A11="","",Pacientes!A11) | G11: =IF(A11="","",IF(B11<>"Sí","Sin consentimiento: excluir sus registros",IF(C11="","Falta fecha de firma",IF(C11>DATE(2026,8,3),"Firmado después del inicio del pretest (declarar)",IF(D11="Sí","Retirado: excluir desde la fecha de retiro","OK")))))
A12: =IF(Pacientes!A12="","",Pacientes!A12) | G12: =IF(A12="","",IF(B12<>"Sí","Sin consentimiento: excluir sus registros",IF(C12="","Falta fecha de firma",IF(C12>DATE(2026,8,3),"Firmado después del inicio del pretest (declarar)",IF(D12="Sí","Retirado: excluir desde la fecha de retiro","OK")))))
A13: =IF(Pacientes!A13="","",Pacientes!A13) | G13: =IF(A13="","",IF(B13<>"Sí","Sin consentimiento: excluir sus registros",IF(C13="","Falta fecha de firma",IF(C13>DATE(2026,8,3),"Firmado después del inicio del pretest (declarar)",IF(D13="Sí","Retirado: excluir desde la fecha de retiro","OK")))))
... A46: =IF(Pacientes!A46="","",Pacientes!A46) | G46: =IF(A46="","",IF(B46<>"Sí","Sin consentimiento: excluir sus registros",IF(C46="","Falta fecha de firma",IF(C46>DATE(2026,8,3),"Firmado después del inicio del pretest (declarar)",IF(D46="Sí","Retirado: excluir desde la fecha de retiro","OK")))))

Sheet Verificacion_VI
A1: Módulo (dimensión VI) | B1: Funcionalidad verificada | C1: Fecha de verificación | D1: Resultado | E1: Evidencia (captura, registro) | F1: Responsable
A2: Registro de pacientes | B2: Alta de un paciente nuevo con validación de campos obligatorios
A3: Registro de pacientes | B3: Almacenamiento del registro con marca de tiempo de inicio y fin
A4: Agendamiento y recordatorios | B4: Creación de una cita con fecha, hora y servicio
A5: Agendamiento y recordatorios | B5: Envío automático del recordatorio al paciente
A6: Agendamiento y recordatorios | B6: Registro de cancelación o reprogramación con aviso previo
A7: Chatbot conversacional | B7: Respuesta a una consulta de cada categoría (citas, horarios, información institucional, requisitos, ubicación, seguimiento)
A8: Chatbot conversacional | B8: Derivación al personal cuando la consulta no puede resolverse
A9: Chatbot conversacional | B9: Registro de cada consulta con su categoría, resolución y derivación

Sheet TPR_PRE
A1: ID registro | B1: Fecha | C1: Código paciente | D1: Hora inicio registro | E1: Hora fin registro | F1: TPR (min) | G1: Modalidad | H1: Control de calidad
A2: Ej. | B2: 46237 | C2: PAC-00 | D2: 0.37638889 | E2: 0.38159722 | F2: =(E2-D2)*1440 | G2: Manual
A3: =IF(B3="","",ROW()-2) | F3: =IF(OR(D3="",E3=""),"",(E3-D3)*1440) | G3: Manual | H3: =IF(B3="","",IF(OR(C3="",D3="",E3=""),"Faltan datos",IF(COUNTIF(Pacientes!$A$2:$A$46,C3)=0,"Código no registrado",IF(F3<=0,"Tiempo no válido",IF(F3>60,"Revisar: más de 60 min","OK")))))
A4: =IF(B4="","",ROW()-2) | F4: =IF(OR(D4="",E4=""),"",(E4-D4)*1440) | G4: Manual | H4: =IF(B4="","",IF(OR(C4="",D4="",E4=""),"Faltan datos",IF(COUNTIF(Pacientes!$A$2:$A$46,C4)=0,"Código no registrado",IF(F4<=0,"Tiempo no válido",IF(F4>60,"Revisar: más de 60 min","OK")))))
A5: =IF(B5="","",ROW()-2) | F5: =IF(OR(D5="",E5=""),"",(E5-D5)*1440) | G5: Manual | H5: =IF(B5="","",IF(OR(C5="",D5="",E5=""),"Faltan datos",IF(COUNTIF(Pacientes!$A$2:$A$46,C5)=0,"Código no registrado",IF(F5<=0,"Tiempo no válido",IF(F5>60,"Revisar: más de 60 min","OK")))))
A6: =IF(B6="","",ROW()-2) | F6: =IF(OR(D6="",E6=""),"",(E6-D6)*1440) | G6: Manual | H6: =IF(B6="","",IF(OR(C6="",D6="",E6=""),"Faltan datos",IF(COUNTIF(Pacientes!$A$2:$A$46,C6)=0,"Código no registrado",IF(F6<=0,"Tiempo no válido",IF(F6>60,"Revisar: más de 60 min","OK")))))
A7: =IF(B7="","",ROW()-2) | F7: =IF(OR(D7="",E7=""),"",(E7-D7)*1440) | G7: Manual | H7: =IF(B7="","",IF(OR(C7="",D7="",E7=""),"Faltan datos",IF(COUNTIF(Pacientes!$A$2:$A$46,C7)=0,"Código no registrado",IF(F7<=0,"Tiempo no válido",IF(F7>60,"Revisar: más de 60 min","OK")))))
A8: =IF(B8="","",ROW()-2) | F8: =IF(OR(D8="",E8=""),"",(E8-D8)*1440) | G8: Manual | H8: =IF(B8="","",IF(OR(C8="",D8="",E8=""),"Faltan datos",IF(COUNTIF(Pacientes!$A$2:$A$46,C8)=0,"Código no registrado",IF(F8<=0,"Tiempo no válido",IF(F8>60,"Revisar: más de 60 min","OK")))))
A9: =IF(B9="","",ROW()-2) | F9: =IF(OR(D9="",E9=""),"",(E9-D9)*1440) | G9: Manual | H9: =IF(B9="","",IF(OR(C9="",D9="",E9=""),"Faltan datos",IF(COUNTIF(Pacientes!$A$2:$A$46,C9)=0,"Código no registrado",IF(F9<=0,"Tiempo no válido",IF(F9>60,"Revisar: más de 60 min","OK")))))
A10: =IF(B10="","",ROW()-2) | F10: =IF(OR(D10="",E10=""),"",(E10-D10)*1440) | G10: Manual | H10: =IF(B10="","",IF(OR(C10="",D10="",E10=""),"Faltan datos",IF(COUNTIF(Pacientes!$A$2:$A$46,C10)=0,"Código no registrado",IF(F10<=0,"Tiempo no válido",IF(F10>60,"Revisar: más de 60 min","OK")))))
A11: =IF(B11="","",ROW()-2) | F11: =IF(OR(D11="",E11=""),"",(E11-D11)*1440) | G11: Manual | H11: =IF(B11="","",IF(OR(C11="",D11="",E11=""),"Faltan datos",IF(COUNTIF(Pacientes!$A$2:$A$46,C11)=0,"Código no registrado",IF(F11<=0,"Tiempo no válido",IF(F11>60,"Revisar: más de 60 min","OK")))))
A12: =IF(B12="","",ROW()-2) | F12: =IF(OR(D12="",E12=""),"",(E12-D12)*1440) | G12: Manual | H12: =IF(B12="","",IF(OR(C12="",D12="",E12=""),"Faltan datos",IF(COUNTIF(Pacientes!$A$2:$A$46,C12)=0,"Código no registrado",IF(F12<=0,"Tiempo no válido",IF(F12>60,"Revisar: más de 60 min","OK")))))
A13: =IF(B13="","",ROW()-2) | F13: =IF(OR(D13="",E13=""),"",(E13-D13)*1440) | G13: Manual | H13: =IF(B13="","",IF(OR(C13="",D13="",E13=""),"Faltan datos",IF(COUNTIF(Pacientes!$A$2:$A$46,C13)=0,"Código no registrado",IF(F13<=0,"Tiempo no válido",IF(F13>60,"Revisar: más de 60 min","OK")))))
A14: =IF(B14="","",ROW()-2) | F14: =IF(OR(D14="",E14=""),"",(E14-D14)*1440) | G14: Manual | H14: =IF(B14="","",IF(OR(C14="",D14="",E14=""),"Faltan datos",IF(COUNTIF(Pacientes!$A$2:$A$46,C14)=0,"Código no registrado",IF(F14<=0,"Tiempo no válido",IF(F14>60,"Revisar: más de 60 min","OK")))))
... A202: =IF(B202="","",ROW()-2) | F202: =IF(OR(D202="",E202=""),"",(E202-D202)*1440) | G202: Manual | H202: =IF(B202="","",IF(OR(C202="",D202="",E202=""),"Faltan datos",IF(COUNTIF(Pacientes!$A$2:$A$46,C202)=0,"Código no registrado",IF(F202<=0,"Tiempo no válido",IF(F202>60,"Revisar: más de 60 min","OK")))))

Sheet TPR_POST
A1: ID registro | B1: Fecha | C1: Código paciente | D1: Hora inicio registro | E1: Hora fin registro | F1: TPR (min) | G1: Modalidad | H1: Control de calidad
A2: Ej. | B2: 46267 | C2: PAC-00 | D2: 0.37638889 | E2: 0.38159722 | F2: =(E2-D2)*1440 | G2: Sistema
A3: =IF(B3="","",ROW()-2) | F3: =IF(OR(D3="",E3=""),"",(E3-D3)*1440) | G3: Sistema | H3: =IF(B3="","",IF(OR(C3="",D3="",E3=""),"Faltan datos",IF(COUNTIF(Pacientes!$A$2:$A$46,C3)=0,"Código no registrado",IF(F3<=0,"Tiempo no válido",IF(F3>60,"Revisar: más de 60 min","OK")))))
A4: =IF(B4="","",ROW()-2) | F4: =IF(OR(D4="",E4=""),"",(E4-D4)*1440) | G4: Sistema | H4: =IF(B4="","",IF(OR(C4="",D4="",E4=""),"Faltan datos",IF(COUNTIF(Pacientes!$A$2:$A$46,C4)=0,"Código no registrado",IF(F4<=0,"Tiempo no válido",IF(F4>60,"Revisar: más de 60 min","OK")))))
A5: =IF(B5="","",ROW()-2) | F5: =IF(OR(D5="",E5=""),"",(E5-D5)*1440) | G5: Sistema | H5: =IF(B5="","",IF(OR(C5="",D5="",E5=""),"Faltan datos",IF(COUNTIF(Pacientes!$A$2:$A$46,C5)=0,"Código no registrado",IF(F5<=0,"Tiempo no válido",IF(F5>60,"Revisar: más de 60 min","OK")))))
A6: =IF(B6="","",ROW()-2) | F6: =IF(OR(D6="",E6=""),"",(E6-D6)*1440) | G6: Sistema | H6: =IF(B6="","",IF(OR(C6="",D6="",E6=""),"Faltan datos",IF(COUNTIF(Pacientes!$A$2:$A$46,C6)=0,"Código no registrado",IF(F6<=0,"Tiempo no válido",IF(F6>60,"Revisar: más de 60 min","OK")))))
A7: =IF(B7="","",ROW()-2) | F7: =IF(OR(D7="",E7=""),"",(E7-D7)*1440) | G7: Sistema | H7: =IF(B7="","",IF(OR(C7="",D7="",E7=""),"Faltan datos",IF(COUNTIF(Pacientes!$A$2:$A$46,C7)=0,"Código no registrado",IF(F7<=0,"Tiempo no válido",IF(F7>60,"Revisar: más de 60 min","OK")))))
A8: =IF(B8="","",ROW()-2) | F8: =IF(OR(D8="",E8=""),"",(E8-D8)*1440) | G8: Sistema | H8: =IF(B8="","",IF(OR(C8="",D8="",E8=""),"Faltan datos",IF(COUNTIF(Pacientes!$A$2:$A$46,C8)=0,"Código no registrado",IF(F8<=0,"Tiempo no válido",IF(F8>60,"Revisar: más de 60 min","OK")))))
A9: =IF(B9="","",ROW()-2) | F9: =IF(OR(D9="",E9=""),"",(E9-D9)*1440) | G9: Sistema | H9: =IF(B9="","",IF(OR(C9="",D9="",E9=""),"Faltan datos",IF(COUNTIF(Pacientes!$A$2:$A$46,C9)=0,"Código no registrado",IF(F9<=0,"Tiempo no válido",IF(F9>60,"Revisar: más de 60 min","OK")))))
A10: =IF(B10="","",ROW()-2) | F10: =IF(OR(D10="",E10=""),"",(E10-D10)*1440) | G10: Sistema | H10: =IF(B10="","",IF(OR(C10="",D10="",E10=""),"Faltan datos",IF(COUNTIF(Pacientes!$A$2:$A$46,C10)=0,"Código no registrado",IF(F10<=0,"Tiempo no válido",IF(F10>60,"Revisar: más de 60 min","OK")))))
A11: =IF(B11="","",ROW()-2) | F11: =IF(OR(D11="",E11=""),"",(E11-D11)*1440) | G11: Sistema | H11: =IF(B11="","",IF(OR(C11="",D11="",E11=""),"Faltan datos",IF(COUNTIF(Pacientes!$A$2:$A$46,C11)=0,"Código no registrado",IF(F11<=0,"Tiempo no válido",IF(F11>60,"Revisar: más de 60 min","OK")))))
A12: =IF(B12="","",ROW()-2) | F12: =IF(OR(D12="",E12=""),"",(E12-D12)*1440) | G12: Sistema | H12: =IF(B12="","",IF(OR(C12="",D12="",E12=""),"Faltan datos",IF(COUNTIF(Pacientes!$A$2:$A$46,C12)=0,"Código no registrado",IF(F12<=0,"Tiempo no válido",IF(F12>60,"Revisar: más de 60 min","OK")))))
A13: =IF(B13="","",ROW()-2) | F13: =IF(OR(D13="",E13=""),"",(E13-D13)*1440) | G13: Sistema | H13: =IF(B13="","",IF(OR(C13="",D13="",E13=""),"Faltan datos",IF(COUNTIF(Pacientes!$A$2:$A$46,C13)=0,"Código no registrado",IF(F13<=0,"Tiempo no válido",IF(F13>60,"Revisar: más de 60 min","OK")))))
A14: =IF(B14="","",ROW()-2) | F14: =IF(OR(D14="",E14=""),"",(E14-D14)*1440) | G14: Sistema | H14: =IF(B14="","",IF(OR(C14="",D14="",E14=""),"Faltan datos",IF(COUNTIF(Pacientes!$A$2:$A$46,C14)=0,"Código no registrado",IF(F14<=0,"Tiempo no válido",IF(F14>60,"Revisar: más de 60 min","OK")))))
... A202: =IF(B202="","",ROW()-2) | F202: =IF(OR(D202="",E202=""),"",(E202-D202)*1440) | G202: Sistema | H202: =IF(B202="","",IF(OR(C202="",D202="",E202=""),"Faltan datos",IF(COUNTIF(Pacientes!$A$2:$A$46,C202)=0,"Código no registrado",IF(F202<=0,"Tiempo no válido",IF(F202>60,"Revisar: más de 60 min","OK")))))

Sheet Ausentismo_PRE
A1: ID cita | B1: Fecha | C1: Código paciente | D1: Cita programada | E1: Estado | F1: Motivo (si no asistió) | G1: Recordatorio enviado | H1: Control de calidad
A2: Ej. | B2: 46237 | C2: PAC-00 | D2: Sí | E2: No asistió | F2: Sin aviso | G2: No
A3: =IF(B3="","",ROW()-2) | H3: =IF(B3="","",IF(OR(C3="",E3=""),"Faltan datos",IF(COUNTIF(Pacientes!$A$2:$A$46,C3)=0,"Código no registrado","OK")))
A4: =IF(B4="","",ROW()-2) | H4: =IF(B4="","",IF(OR(C4="",E4=""),"Faltan datos",IF(COUNTIF(Pacientes!$A$2:$A$46,C4)=0,"Código no registrado","OK")))
A5: =IF(B5="","",ROW()-2) | H5: =IF(B5="","",IF(OR(C5="",E5=""),"Faltan datos",IF(COUNTIF(Pacientes!$A$2:$A$46,C5)=0,"Código no registrado","OK")))
A6: =IF(B6="","",ROW()-2) | H6: =IF(B6="","",IF(OR(C6="",E6=""),"Faltan datos",IF(COUNTIF(Pacientes!$A$2:$A$46,C6)=0,"Código no registrado","OK")))
A7: =IF(B7="","",ROW()-2) | H7: =IF(B7="","",IF(OR(C7="",E7=""),"Faltan datos",IF(COUNTIF(Pacientes!$A$2:$A$46,C7)=0,"Código no registrado","OK")))
A8: =IF(B8="","",ROW()-2) | H8: =IF(B8="","",IF(OR(C8="",E8=""),"Faltan datos",IF(COUNTIF(Pacientes!$A$2:$A$46,C8)=0,"Código no registrado","OK")))
A9: =IF(B9="","",ROW()-2) | H9: =IF(B9="","",IF(OR(C9="",E9=""),"Faltan datos",IF(COUNTIF(Pacientes!$A$2:$A$46,C9)=0,"Código no registrado","OK")))
A10: =IF(B10="","",ROW()-2) | H10: =IF(B10="","",IF(OR(C10="",E10=""),"Faltan datos",IF(COUNTIF(Pacientes!$A$2:$A$46,C10)=0,"Código no registrado","OK")))
A11: =IF(B11="","",ROW()-2) | H11: =IF(B11="","",IF(OR(C11="",E11=""),"Faltan datos",IF(COUNTIF(Pacientes!$A$2:$A$46,C11)=0,"Código no registrado","OK")))
A12: =IF(B12="","",ROW()-2) | H12: =IF(B12="","",IF(OR(C12="",E12=""),"Faltan datos",IF(COUNTIF(Pacientes!$A$2:$A$46,C12)=0,"Código no registrado","OK")))
A13: =IF(B13="","",ROW()-2) | H13: =IF(B13="","",IF(OR(C13="",E13=""),"Faltan datos",IF(COUNTIF(Pacientes!$A$2:$A$46,C13)=0,"Código no registrado","OK")))
A14: =IF(B14="","",ROW()-2) | H14: =IF(B14="","",IF(OR(C14="",E14=""),"Faltan datos",IF(COUNTIF(Pacientes!$A$2:$A$46,C14)=0,"Código no registrado","OK")))
... A202: =IF(B202="","",ROW()-2) | H202: =IF(B202="","",IF(OR(C202="",E202=""),"Faltan datos",IF(COUNTIF(Pacientes!$A$2:$A$46,C202)=0,"Código no registrado","OK")))

Sheet Ausentismo_POST
A1: ID cita | B1: Fecha | C1: Código paciente | D1: Cita programada | E1: Estado | F1: Motivo (si no asistió) | G1: Recordatorio enviado | H1: Control de calidad
A2: Ej. | B2: 46267 | C2: PAC-00 | D2: Sí | E2: No asistió | F2: Sin aviso | G2: No
A3: =IF(B3="","",ROW()-2) | H3: =IF(B3="","",IF(OR(C3="",E3=""),"Faltan datos",IF(COUNTIF(Pacientes!$A$2:$A$46,C3)=0,"Código no registrado","OK")))
A4: =IF(B4="","",ROW()-2) | H4: =IF(B4="","",IF(OR(C4="",E4=""),"Faltan datos",IF(COUNTIF(Pacientes!$A$2:$A$46,C4)=0,"Código no registrado","OK")))
A5: =IF(B5="","",ROW()-2) | H5: =IF(B5="","",IF(OR(C5="",E5=""),"Faltan datos",IF(COUNTIF(Pacientes!$A$2:$A$46,C5)=0,"Código no registrado","OK")))
A6: =IF(B6="","",ROW()-2) | H6: =IF(B6="","",IF(OR(C6="",E6=""),"Faltan datos",IF(COUNTIF(Pacientes!$A$2:$A$46,C6)=0,"Código no registrado","OK")))
A7: =IF(B7="","",ROW()-2) | H7: =IF(B7="","",IF(OR(C7="",E7=""),"Faltan datos",IF(COUNTIF(Pacientes!$A$2:$A$46,C7)=0,"Código no registrado","OK")))
A8: =IF(B8="","",ROW()-2) | H8: =IF(B8="","",IF(OR(C8="",E8=""),"Faltan datos",IF(COUNTIF(Pacientes!$A$2:$A$46,C8)=0,"Código no registrado","OK")))
A9: =IF(B9="","",ROW()-2) | H9: =IF(B9="","",IF(OR(C9="",E9=""),"Faltan datos",IF(COUNTIF(Pacientes!$A$2:$A$46,C9)=0,"Código no registrado","OK")))
A10: =IF(B10="","",ROW()-2) | H10: =IF(B10="","",IF(OR(C10="",E10=""),"Faltan datos",IF(COUNTIF(Pacientes!$A$2:$A$46,C10)=0,"Código no registrado","OK")))
A11: =IF(B11="","",ROW()-2) | H11: =IF(B11="","",IF(OR(C11="",E11=""),"Faltan datos",IF(COUNTIF(Pacientes!$A$2:$A$46,C11)=0,"Código no registrado","OK")))
A12: =IF(B12="","",ROW()-2) | H12: =IF(B12="","",IF(OR(C12="",E12=""),"Faltan datos",IF(COUNTIF(Pacientes!$A$2:$A$46,C12)=0,"Código no registrado","OK")))
A13: =IF(B13="","",ROW()-2) | H13: =IF(B13="","",IF(OR(C13="",E13=""),"Faltan datos",IF(COUNTIF(Pacientes!$A$2:$A$46,C13)=0,"Código no registrado","OK")))
A14: =IF(B14="","",ROW()-2) | H14: =IF(B14="","",IF(OR(C14="",E14=""),"Faltan datos",IF(COUNTIF(Pacientes!$A$2:$A$46,C14)=0,"Código no registrado","OK")))
... A202: =IF(B202="","",ROW()-2) | H202: =IF(B202="","",IF(OR(C202="",E202=""),"Faltan datos",IF(COUNTIF(Pacientes!$A$2:$A$46,C202)=0,"Código no registrado","OK")))

Sheet Consultas_PRE
A1: ID consulta | B1: Fecha | C1: Código paciente | D1: Categoría | E1: Canal | F1: Resuelta en el primer contacto | G1: Derivada a otra persona o área | H1: Tiempo de respuesta (min) | I1: Control de calidad
A2: Ej. | B2: 46237 | C2: PAC-00 | D2: Horarios | E2: Presencial | F2: Sí | G2: No | H2: 3
A3: =IF(B3="","",ROW()-2) | I3: =IF(B3="","",IF(OR(D3="",F3="",G3=""),"Faltan datos",IF(AND(C3<>"",COUNTIF(Pacientes!$A$2:$A$46,C3)=0),"Código no registrado",IF(AND(F3="Sí",G3="Sí"),"Contradicción: resuelta y derivada","OK"))))
A4: =IF(B4="","",ROW()-2) | I4: =IF(B4="","",IF(OR(D4="",F4="",G4=""),"Faltan datos",IF(AND(C4<>"",COUNTIF(Pacientes!$A$2:$A$46,C4)=0),"Código no registrado",IF(AND(F4="Sí",G4="Sí"),"Contradicción: resuelta y derivada","OK"))))
A5: =IF(B5="","",ROW()-2) | I5: =IF(B5="","",IF(OR(D5="",F5="",G5=""),"Faltan datos",IF(AND(C5<>"",COUNTIF(Pacientes!$A$2:$A$46,C5)=0),"Código no registrado",IF(AND(F5="Sí",G5="Sí"),"Contradicción: resuelta y derivada","OK"))))
A6: =IF(B6="","",ROW()-2) | I6: =IF(B6="","",IF(OR(D6="",F6="",G6=""),"Faltan datos",IF(AND(C6<>"",COUNTIF(Pacientes!$A$2:$A$46,C6)=0),"Código no registrado",IF(AND(F6="Sí",G6="Sí"),"Contradicción: resuelta y derivada","OK"))))
A7: =IF(B7="","",ROW()-2) | I7: =IF(B7="","",IF(OR(D7="",F7="",G7=""),"Faltan datos",IF(AND(C7<>"",COUNTIF(Pacientes!$A$2:$A$46,C7)=0),"Código no registrado",IF(AND(F7="Sí",G7="Sí"),"Contradicción: resuelta y derivada","OK"))))
A8: =IF(B8="","",ROW()-2) | I8: =IF(B8="","",IF(OR(D8="",F8="",G8=""),"Faltan datos",IF(AND(C8<>"",COUNTIF(Pacientes!$A$2:$A$46,C8)=0),"Código no registrado",IF(AND(F8="Sí",G8="Sí"),"Contradicción: resuelta y derivada","OK"))))
A9: =IF(B9="","",ROW()-2) | I9: =IF(B9="","",IF(OR(D9="",F9="",G9=""),"Faltan datos",IF(AND(C9<>"",COUNTIF(Pacientes!$A$2:$A$46,C9)=0),"Código no registrado",IF(AND(F9="Sí",G9="Sí"),"Contradicción: resuelta y derivada","OK"))))
A10: =IF(B10="","",ROW()-2) | I10: =IF(B10="","",IF(OR(D10="",F10="",G10=""),"Faltan datos",IF(AND(C10<>"",COUNTIF(Pacientes!$A$2:$A$46,C10)=0),"Código no registrado",IF(AND(F10="Sí",G10="Sí"),"Contradicción: resuelta y derivada","OK"))))
A11: =IF(B11="","",ROW()-2) | I11: =IF(B11="","",IF(OR(D11="",F11="",G11=""),"Faltan datos",IF(AND(C11<>"",COUNTIF(Pacientes!$A$2:$A$46,C11)=0),"Código no registrado",IF(AND(F11="Sí",G11="Sí"),"Contradicción: resuelta y derivada","OK"))))
A12: =IF(B12="","",ROW()-2) | I12: =IF(B12="","",IF(OR(D12="",F12="",G12=""),"Faltan datos",IF(AND(C12<>"",COUNTIF(Pacientes!$A$2:$A$46,C12)=0),"Código no registrado",IF(AND(F12="Sí",G12="Sí"),"Contradicción: resuelta y derivada","OK"))))
A13: =IF(B13="","",ROW()-2) | I13: =IF(B13="","",IF(OR(D13="",F13="",G13=""),"Faltan datos",IF(AND(C13<>"",COUNTIF(Pacientes!$A$2:$A$46,C13)=0),"Código no registrado",IF(AND(F13="Sí",G13="Sí"),"Contradicción: resuelta y derivada","OK"))))
A14: =IF(B14="","",ROW()-2) | I14: =IF(B14="","",IF(OR(D14="",F14="",G14=""),"Faltan datos",IF(AND(C14<>"",COUNTIF(Pacientes!$A$2:$A$46,C14)=0),"Código no registrado",IF(AND(F14="Sí",G14="Sí"),"Contradicción: resuelta y derivada","OK"))))
... A202: =IF(B202="","",ROW()-2) | I202: =IF(B202="","",IF(OR(D202="",F202="",G202=""),"Faltan datos",IF(AND(C202<>"",COUNTIF(Pacientes!$A$2:$A$46,C202)=0),"Código no registrado",IF(AND(F202="Sí",G202="Sí"),"Contradicción: resuelta y derivada","OK"))))

Sheet Consultas_POST
A1: ID consulta | B1: Fecha | C1: Código paciente | D1: Categoría | E1: Canal | F1: Resuelta en el primer contacto | G1: Derivada a otra persona o área | H1: Tiempo de respuesta (min) | I1: Control de calidad
A2: Ej. | B2: 46267 | C2: PAC-00 | D2: Horarios | E2: Chatbot | F2: Sí | G2: No | H2: 3
A3: =IF(B3="","",ROW()-2) | E3: Chatbot | I3: =IF(B3="","",IF(OR(D3="",F3="",G3=""),"Faltan datos",IF(AND(C3<>"",COUNTIF(Pacientes!$A$2:$A$46,C3)=0),"Código no registrado",IF(AND(F3="Sí",G3="Sí"),"Contradicción: resuelta y derivada","OK"))))
A4: =IF(B4="","",ROW()-2) | E4: Chatbot | I4: =IF(B4="","",IF(OR(D4="",F4="",G4=""),"Faltan datos",IF(AND(C4<>"",COUNTIF(Pacientes!$A$2:$A$46,C4)=0),"Código no registrado",IF(AND(F4="Sí",G4="Sí"),"Contradicción: resuelta y derivada","OK"))))
A5: =IF(B5="","",ROW()-2) | E5: Chatbot | I5: =IF(B5="","",IF(OR(D5="",F5="",G5=""),"Faltan datos",IF(AND(C5<>"",COUNTIF(Pacientes!$A$2:$A$46,C5)=0),"Código no registrado",IF(AND(F5="Sí",G5="Sí"),"Contradicción: resuelta y derivada","OK"))))
A6: =IF(B6="","",ROW()-2) | E6: Chatbot | I6: =IF(B6="","",IF(OR(D6="",F6="",G6=""),"Faltan datos",IF(AND(C6<>"",COUNTIF(Pacientes!$A$2:$A$46,C6)=0),"Código no registrado",IF(AND(F6="Sí",G6="Sí"),"Contradicción: resuelta y derivada","OK"))))
A7: =IF(B7="","",ROW()-2) | E7: Chatbot | I7: =IF(B7="","",IF(OR(D7="",F7="",G7=""),"Faltan datos",IF(AND(C7<>"",COUNTIF(Pacientes!$A$2:$A$46,C7)=0),"Código no registrado",IF(AND(F7="Sí",G7="Sí"),"Contradicción: resuelta y derivada","OK"))))
A8: =IF(B8="","",ROW()-2) | E8: Chatbot | I8: =IF(B8="","",IF(OR(D8="",F8="",G8=""),"Faltan datos",IF(AND(C8<>"",COUNTIF(Pacientes!$A$2:$A$46,C8)=0),"Código no registrado",IF(AND(F8="Sí",G8="Sí"),"Contradicción: resuelta y derivada","OK"))))
A9: =IF(B9="","",ROW()-2) | E9: Chatbot | I9: =IF(B9="","",IF(OR(D9="",F9="",G9=""),"Faltan datos",IF(AND(C9<>"",COUNTIF(Pacientes!$A$2:$A$46,C9)=0),"Código no registrado",IF(AND(F9="Sí",G9="Sí"),"Contradicción: resuelta y derivada","OK"))))
A10: =IF(B10="","",ROW()-2) | E10: Chatbot | I10: =IF(B10="","",IF(OR(D10="",F10="",G10=""),"Faltan datos",IF(AND(C10<>"",COUNTIF(Pacientes!$A$2:$A$46,C10)=0),"Código no registrado",IF(AND(F10="Sí",G10="Sí"),"Contradicción: resuelta y derivada","OK"))))
A11: =IF(B11="","",ROW()-2) | E11: Chatbot | I11: =IF(B11="","",IF(OR(D11="",F11="",G11=""),"Faltan datos",IF(AND(C11<>"",COUNTIF(Pacientes!$A$2:$A$46,C11)=0),"Código no registrado",IF(AND(F11="Sí",G11="Sí"),"Contradicción: resuelta y derivada","OK"))))
A12: =IF(B12="","",ROW()-2) | E12: Chatbot | I12: =IF(B12="","",IF(OR(D12="",F12="",G12=""),"Faltan datos",IF(AND(C12<>"",COUNTIF(Pacientes!$A$2:$A$46,C12)=0),"Código no registrado",IF(AND(F12="Sí",G12="Sí"),"Contradicción: resuelta y derivada","OK"))))
A13: =IF(B13="","",ROW()-2) | E13: Chatbot | I13: =IF(B13="","",IF(OR(D13="",F13="",G13=""),"Faltan datos",IF(AND(C13<>"",COUNTIF(Pacientes!$A$2:$A$46,C13)=0),"Código no registrado",IF(AND(F13="Sí",G13="Sí"),"Contradicción: resuelta y derivada","OK"))))
A14: =IF(B14="","",ROW()-2) | E14: Chatbot | I14: =IF(B14="","",IF(OR(D14="",F14="",G14=""),"Faltan datos",IF(AND(C14<>"",COUNTIF(Pacientes!$A$2:$A$46,C14)=0),"Código no registrado",IF(AND(F14="Sí",G14="Sí"),"Contradicción: resuelta y derivada","OK"))))
... A202: =IF(B202="","",ROW()-2) | E202: Chatbot | I202: =IF(B202="","",IF(OR(D202="",F202="",G202=""),"Faltan datos",IF(AND(C202<>"",COUNTIF(Pacientes!$A$2:$A$46,C202)=0),"Código no registrado",IF(AND(F202="Sí",G202="Sí"),"Contradicción: resuelta y derivada","OK"))))

Sheet Sesiones
A1: Par | B1: Fecha PRE | C1: TPR PRE (min) | D1: Ausentismo PRE (%) | E1: Consultas PRE (%) | F1: Fecha POST | G1: TPR POST (min) | H1: Ausentismo POST (%) | I1: Consultas POST (%) | J1: Registros PRE | K1: Citas elegibles PRE | L1: Consultas PRE | M1: Registros POST | N1: Citas elegibles POST | O1: Consultas POST | P1: Par válido TPR | Q1: Par válido TA | R1: Par válido NCA | S1: Mismo día de semana
A2: 1 | B2: 46237 | C2: =IFERROR(AVERAGEIFS(TPR_PRE!$F$3:$F$202,TPR_PRE!$B$3:$B$202,B2),"") | D2: =IFERROR(COUNTIFS(Ausentismo_PRE!$B$3:$B$202,B2,Ausentismo_PRE!$E$3:$E$202,"No asistió")/(COUNTIFS(Ausentismo_PRE!$B$3:$B$202,B2,Ausentismo_PRE!$E$3:$E$202,"No asistió")+COUNTIFS(Ausentismo_PRE!$B$3:$B$202,B2,Ausentismo_PRE!$E$3:$E$202,"Asistió")),"") | E2: =IFERROR(COUNTIFS(Consultas_PRE!$B$3:$B$202,B2,Consultas_PRE!$F$3:$F$202,"Sí",Consultas_PRE!$G$3:$G$202,"No")/COUNTIFS(Consultas_PRE!$B$3:$B$202,B2),"") | F2: 46272 | G2: =IFERROR(AVERAGEIFS(TPR_POST!$F$3:$F$202,TPR_POST!$B$3:$B$202,F2),"") | H2: =IFERROR(COUNTIFS(Ausentismo_POST!$B$3:$B$202,F2,Ausentismo_POST!$E$3:$E$202,"No asistió")/(COUNTIFS(Ausentismo_POST!$B$3:$B$202,F2,Ausentismo_POST!$E$3:$E$202,"No asistió")+COUNTIFS(Ausentismo_POST!$B$3:$B$202,F2,Ausentismo_POST!$E$3:$E$202,"Asistió")),"") | I2: =IFERROR(COUNTIFS(Consultas_POST!$B$3:$B$202,F2,Consultas_POST!$F$3:$F$202,"Sí",Consultas_POST!$G$3:$G$202,"No")/COUNTIFS(Consultas_POST!$B$3:$B$202,F2),"") | J2: =COUNTIFS(TPR_PRE!$B$3:$B$202,B2,TPR_PRE!$F$3:$F$202,">=0") | K2: =COUNTIFS(Ausentismo_PRE!$B$3:$B$202,B2,Ausentismo_PRE!$E$3:$E$202,"No asistió")+COUNTIFS(Ausentismo_PRE!$B$3:$B$202,B2,Ausentismo_PRE!$E$3:$E$202,"Asistió") | L2: =COUNTIFS(Consultas_PRE!$B$3:$B$202,B2) | M2: =COUNTIFS(TPR_POST!$B$3:$B$202,F2,TPR_POST!$F$3:$F$202,">=0") | N2: =COUNTIFS(Ausentismo_POST!$B$3:$B$202,F2,Ausentismo_POST!$E$3:$E$202,"No asistió")+COUNTIFS(Ausentismo_POST!$B$3:$B$202,F2,Ausentismo_POST!$E$3:$E$202,"Asistió") | O2: =COUNTIFS(Consultas_POST!$B$3:$B$202,F2) | P2: =IF(AND(J2>0,M2>0),"Sí","No") | Q2: =IF(AND(K2>0,N2>0),"Sí","No") | R2: =IF(AND(L2>0,O2>0),"Sí","No") | S2: =IF(WEEKDAY(B2)=WEEKDAY(F2),"Sí","No")
A3: 2 | B3: 46239 | C3: =IFERROR(AVERAGEIFS(TPR_PRE!$F$3:$F$202,TPR_PRE!$B$3:$B$202,B3),"") | D3: =IFERROR(COUNTIFS(Ausentismo_PRE!$B$3:$B$202,B3,Ausentismo_PRE!$E$3:$E$202,"No asistió")/(COUNTIFS(Ausentismo_PRE!$B$3:$B$202,B3,Ausentismo_PRE!$E$3:$E$202,"No asistió")+COUNTIFS(Ausentismo_PRE!$B$3:$B$202,B3,Ausentismo_PRE!$E$3:$E$202,"Asistió")),"") | E3: =IFERROR(COUNTIFS(Consultas_PRE!$B$3:$B$202,B3,Consultas_PRE!$F$3:$F$202,"Sí",Consultas_PRE!$G$3:$G$202,"No")/COUNTIFS(Consultas_PRE!$B$3:$B$202,B3),"") | F3: 46267 | G3: =IFERROR(AVERAGEIFS(TPR_POST!$F$3:$F$202,TPR_POST!$B$3:$B$202,F3),"") | H3: =IFERROR(COUNTIFS(Ausentismo_POST!$B$3:$B$202,F3,Ausentismo_POST!$E$3:$E$202,"No asistió")/(COUNTIFS(Ausentismo_POST!$B$3:$B$202,F3,Ausentismo_POST!$E$3:$E$202,"No asistió")+COUNTIFS(Ausentismo_POST!$B$3:$B$202,F3,Ausentismo_POST!$E$3:$E$202,"Asistió")),"") | I3: =IFERROR(COUNTIFS(Consultas_POST!$B$3:$B$202,F3,Consultas_POST!$F$3:$F$202,"Sí",Consultas_POST!$G$3:$G$202,"No")/COUNTIFS(Consultas_POST!$B$3:$B$202,F3),"") | J3: =COUNTIFS(TPR_PRE!$B$3:$B$202,B3,TPR_PRE!$F$3:$F$202,">=0") | K3: =COUNTIFS(Ausentismo_PRE!$B$3:$B$202,B3,Ausentismo_PRE!$E$3:$E$202,"No asistió")+COUNTIFS(Ausentismo_PRE!$B$3:$B$202,B3,Ausentismo_PRE!$E$3:$E$202,"Asistió") | L3: =COUNTIFS(Consultas_PRE!$B$3:$B$202,B3) | M3: =COUNTIFS(TPR_POST!$B$3:$B$202,F3,TPR_POST!$F$3:$F$202,">=0") | N3: =COUNTIFS(Ausentismo_POST!$B$3:$B$202,F3,Ausentismo_POST!$E$3:$E$202,"No asistió")+COUNTIFS(Ausentismo_POST!$B$3:$B$202,F3,Ausentismo_POST!$E$3:$E$202,"Asistió") | O3: =COUNTIFS(Consultas_POST!$B$3:$B$202,F3) | P3: =IF(AND(J3>0,M3>0),"Sí","No") | Q3: =IF(AND(K3>0,N3>0),"Sí","No") | R3: =IF(AND(L3>0,O3>0),"Sí","No") | S3: =IF(WEEKDAY(B3)=WEEKDAY(F3),"Sí","No")
A4: 3 | B4: 46241 | C4: =IFERROR(AVERAGEIFS(TPR_PRE!$F$3:$F$202,TPR_PRE!$B$3:$B$202,B4),"") | D4: =IFERROR(COUNTIFS(Ausentismo_PRE!$B$3:$B$202,B4,Ausentismo_PRE!$E$3:$E$202,"No asistió")/(COUNTIFS(Ausentismo_PRE!$B$3:$B$202,B4,Ausentismo_PRE!$E$3:$E$202,"No asistió")+COUNTIFS(Ausentismo_PRE!$B$3:$B$202,B4,Ausentismo_PRE!$E$3:$E$202,"Asistió")),"") | E4: =IFERROR(COUNTIFS(Consultas_PRE!$B$3:$B$202,B4,Consultas_PRE!$F$3:$F$202,"Sí",Consultas_PRE!$G$3:$G$202,"No")/COUNTIFS(Consultas_PRE!$B$3:$B$202,B4),"") | F4: 46269 | G4: =IFERROR(AVERAGEIFS(TPR_POST!$F$3:$F$202,TPR_POST!$B$3:$B$202,F4),"") | H4: =IFERROR(COUNTIFS(Ausentismo_POST!$B$3:$B$202,F4,Ausentismo_POST!$E$3:$E$202,"No asistió")/(COUNTIFS(Ausentismo_POST!$B$3:$B$202,F4,Ausentismo_POST!$E$3:$E$202,"No asistió")+COUNTIFS(Ausentismo_POST!$B$3:$B$202,F4,Ausentismo_POST!$E$3:$E$202,"Asistió")),"") | I4: =IFERROR(COUNTIFS(Consultas_POST!$B$3:$B$202,F4,Consultas_POST!$F$3:$F$202,"Sí",Consultas_POST!$G$3:$G$202,"No")/COUNTIFS(Consultas_POST!$B$3:$B$202,F4),"") | J4: =COUNTIFS(TPR_PRE!$B$3:$B$202,B4,TPR_PRE!$F$3:$F$202,">=0") | K4: =COUNTIFS(Ausentismo_PRE!$B$3:$B$202,B4,Ausentismo_PRE!$E$3:$E$202,"No asistió")+COUNTIFS(Ausentismo_PRE!$B$3:$B$202,B4,Ausentismo_PRE!$E$3:$E$202,"Asistió") | L4: =COUNTIFS(Consultas_PRE!$B$3:$B$202,B4) | M4: =COUNTIFS(TPR_POST!$B$3:$B$202,F4,TPR_POST!$F$3:$F$202,">=0") | N4: =COUNTIFS(Ausentismo_POST!$B$3:$B$202,F4,Ausentismo_POST!$E$3:$E$202,"No asistió")+COUNTIFS(Ausentismo_POST!$B$3:$B$202,F4,Ausentismo_POST!$E$3:$E$202,"Asistió") | O4: =COUNTIFS(Consultas_POST!$B$3:$B$202,F4) | P4: =IF(AND(J4>0,M4>0),"Sí","No") | Q4: =IF(AND(K4>0,N4>0),"Sí","No") | R4: =IF(AND(L4>0,O4>0),"Sí","No") | S4: =IF(WEEKDAY(B4)=WEEKDAY(F4),"Sí","No")
A5: 4 | B5: 46244 | C5: =IFERROR(AVERAGEIFS(TPR_PRE!$F$3:$F$202,TPR_PRE!$B$3:$B$202,B5),"") | D5: =IFERROR(COUNTIFS(Ausentismo_PRE!$B$3:$B$202,B5,Ausentismo_PRE!$E$3:$E$202,"No asistió")/(COUNTIFS(Ausentismo_PRE!$B$3:$B$202,B5,Ausentismo_PRE!$E$3:$E$202,"No asistió")+COUNTIFS(Ausentismo_PRE!$B$3:$B$202,B5,Ausentismo_PRE!$E$3:$E$202,"Asistió")),"") | E5: =IFERROR(COUNTIFS(Consultas_PRE!$B$3:$B$202,B5,Consultas_PRE!$F$3:$F$202,"Sí",Consultas_PRE!$G$3:$G$202,"No")/COUNTIFS(Consultas_PRE!$B$3:$B$202,B5),"") | F5: 46279 | G5: =IFERROR(AVERAGEIFS(TPR_POST!$F$3:$F$202,TPR_POST!$B$3:$B$202,F5),"") | H5: =IFERROR(COUNTIFS(Ausentismo_POST!$B$3:$B$202,F5,Ausentismo_POST!$E$3:$E$202,"No asistió")/(COUNTIFS(Ausentismo_POST!$B$3:$B$202,F5,Ausentismo_POST!$E$3:$E$202,"No asistió")+COUNTIFS(Ausentismo_POST!$B$3:$B$202,F5,Ausentismo_POST!$E$3:$E$202,"Asistió")),"") | I5: =IFERROR(COUNTIFS(Consultas_POST!$B$3:$B$202,F5,Consultas_POST!$F$3:$F$202,"Sí",Consultas_POST!$G$3:$G$202,"No")/COUNTIFS(Consultas_POST!$B$3:$B$202,F5),"") | J5: =COUNTIFS(TPR_PRE!$B$3:$B$202,B5,TPR_PRE!$F$3:$F$202,">=0") | K5: =COUNTIFS(Ausentismo_PRE!$B$3:$B$202,B5,Ausentismo_PRE!$E$3:$E$202,"No asistió")+COUNTIFS(Ausentismo_PRE!$B$3:$B$202,B5,Ausentismo_PRE!$E$3:$E$202,"Asistió") | L5: =COUNTIFS(Consultas_PRE!$B$3:$B$202,B5) | M5: =COUNTIFS(TPR_POST!$B$3:$B$202,F5,TPR_POST!$F$3:$F$202,">=0") | N5: =COUNTIFS(Ausentismo_POST!$B$3:$B$202,F5,Ausentismo_POST!$E$3:$E$202,"No asistió")+COUNTIFS(Ausentismo_POST!$B$3:$B$202,F5,Ausentismo_POST!$E$3:$E$202,"Asistió") | O5: =COUNTIFS(Consultas_POST!$B$3:$B$202,F5) | P5: =IF(AND(J5>0,M5>0),"Sí","No") | Q5: =IF(AND(K5>0,N5>0),"Sí","No") | R5: =IF(AND(L5>0,O5>0),"Sí","No") | S5: =IF(WEEKDAY(B5)=WEEKDAY(F5),"Sí","No")
A6: 5 | B6: 46246 | C6: =IFERROR(AVERAGEIFS(TPR_PRE!$F$3:$F$202,TPR_PRE!$B$3:$B$202,B6),"") | D6: =IFERROR(COUNTIFS(Ausentismo_PRE!$B$3:$B$202,B6,Ausentismo_PRE!$E$3:$E$202,"No asistió")/(COUNTIFS(Ausentismo_PRE!$B$3:$B$202,B6,Ausentismo_PRE!$E$3:$E$202,"No asistió")+COUNTIFS(Ausentismo_PRE!$B$3:$B$202,B6,Ausentismo_PRE!$E$3:$E$202,"Asistió")),"") | E6: =IFERROR(COUNTIFS(Consultas_PRE!$B$3:$B$202,B6,Consultas_PRE!$F$3:$F$202,"Sí",Consultas_PRE!$G$3:$G$202,"No")/COUNTIFS(Consultas_PRE!$B$3:$B$202,B6),"") | F6: 46274 | G6: =IFERROR(AVERAGEIFS(TPR_POST!$F$3:$F$202,TPR_POST!$B$3:$B$202,F6),"") | H6: =IFERROR(COUNTIFS(Ausentismo_POST!$B$3:$B$202,F6,Ausentismo_POST!$E$3:$E$202,"No asistió")/(COUNTIFS(Ausentismo_POST!$B$3:$B$202,F6,Ausentismo_POST!$E$3:$E$202,"No asistió")+COUNTIFS(Ausentismo_POST!$B$3:$B$202,F6,Ausentismo_POST!$E$3:$E$202,"Asistió")),"") | I6: =IFERROR(COUNTIFS(Consultas_POST!$B$3:$B$202,F6,Consultas_POST!$F$3:$F$202,"Sí",Consultas_POST!$G$3:$G$202,"No")/COUNTIFS(Consultas_POST!$B$3:$B$202,F6),"") | J6: =COUNTIFS(TPR_PRE!$B$3:$B$202,B6,TPR_PRE!$F$3:$F$202,">=0") | K6: =COUNTIFS(Ausentismo_PRE!$B$3:$B$202,B6,Ausentismo_PRE!$E$3:$E$202,"No asistió")+COUNTIFS(Ausentismo_PRE!$B$3:$B$202,B6,Ausentismo_PRE!$E$3:$E$202,"Asistió") | L6: =COUNTIFS(Consultas_PRE!$B$3:$B$202,B6) | M6: =COUNTIFS(TPR_POST!$B$3:$B$202,F6,TPR_POST!$F$3:$F$202,">=0") | N6: =COUNTIFS(Ausentismo_POST!$B$3:$B$202,F6,Ausentismo_POST!$E$3:$E$202,"No asistió")+COUNTIFS(Ausentismo_POST!$B$3:$B$202,F6,Ausentismo_POST!$E$3:$E$202,"Asistió") | O6: =COUNTIFS(Consultas_POST!$B$3:$B$202,F6) | P6: =IF(AND(J6>0,M6>0),"Sí","No") | Q6: =IF(AND(K6>0,N6>0),"Sí","No") | R6: =IF(AND(L6>0,O6>0),"Sí","No") | S6: =IF(WEEKDAY(B6)=WEEKDAY(F6),"Sí","No")
A7: 6 | B7: 46248 | C7: =IFERROR(AVERAGEIFS(TPR_PRE!$F$3:$F$202,TPR_PRE!$B$3:$B$202,B7),"") | D7: =IFERROR(COUNTIFS(Ausentismo_PRE!$B$3:$B$202,B7,Ausentismo_PRE!$E$3:$E$202,"No asistió")/(COUNTIFS(Ausentismo_PRE!$B$3:$B$202,B7,Ausentismo_PRE!$E$3:$E$202,"No asistió")+COUNTIFS(Ausentismo_PRE!$B$3:$B$202,B7,Ausentismo_PRE!$E$3:$E$202,"Asistió")),"") | E7: =IFERROR(COUNTIFS(Consultas_PRE!$B$3:$B$202,B7,Consultas_PRE!$F$3:$F$202,"Sí",Consultas_PRE!$G$3:$G$202,"No")/COUNTIFS(Consultas_PRE!$B$3:$B$202,B7),"") | F7: 46276 | G7: =IFERROR(AVERAGEIFS(TPR_POST!$F$3:$F$202,TPR_POST!$B$3:$B$202,F7),"") | H7: =IFERROR(COUNTIFS(Ausentismo_POST!$B$3:$B$202,F7,Ausentismo_POST!$E$3:$E$202,"No asistió")/(COUNTIFS(Ausentismo_POST!$B$3:$B$202,F7,Ausentismo_POST!$E$3:$E$202,"No asistió")+COUNTIFS(Ausentismo_POST!$B$3:$B$202,F7,Ausentismo_POST!$E$3:$E$202,"Asistió")),"") | I7: =IFERROR(COUNTIFS(Consultas_POST!$B$3:$B$202,F7,Consultas_POST!$F$3:$F$202,"Sí",Consultas_POST!$G$3:$G$202,"No")/COUNTIFS(Consultas_POST!$B$3:$B$202,F7),"") | J7: =COUNTIFS(TPR_PRE!$B$3:$B$202,B7,TPR_PRE!$F$3:$F$202,">=0") | K7: =COUNTIFS(Ausentismo_PRE!$B$3:$B$202,B7,Ausentismo_PRE!$E$3:$E$202,"No asistió")+COUNTIFS(Ausentismo_PRE!$B$3:$B$202,B7,Ausentismo_PRE!$E$3:$E$202,"Asistió") | L7: =COUNTIFS(Consultas_PRE!$B$3:$B$202,B7) | M7: =COUNTIFS(TPR_POST!$B$3:$B$202,F7,TPR_POST!$F$3:$F$202,">=0") | N7: =COUNTIFS(Ausentismo_POST!$B$3:$B$202,F7,Ausentismo_POST!$E$3:$E$202,"No asistió")+COUNTIFS(Ausentismo_POST!$B$3:$B$202,F7,Ausentismo_POST!$E$3:$E$202,"Asistió") | O7: =COUNTIFS(Consultas_POST!$B$3:$B$202,F7) | P7: =IF(AND(J7>0,M7>0),"Sí","No") | Q7: =IF(AND(K7>0,N7>0),"Sí","No") | R7: =IF(AND(L7>0,O7>0),"Sí","No") | S7: =IF(WEEKDAY(B7)=WEEKDAY(F7),"Sí","No")
A8: 7 | B8: 46251 | C8: =IFERROR(AVERAGEIFS(TPR_PRE!$F$3:$F$202,TPR_PRE!$B$3:$B$202,B8),"") | D8: =IFERROR(COUNTIFS(Ausentismo_PRE!$B$3:$B$202,B8,Ausentismo_PRE!$E$3:$E$202,"No asistió")/(COUNTIFS(Ausentismo_PRE!$B$3:$B$202,B8,Ausentismo_PRE!$E$3:$E$202,"No asistió")+COUNTIFS(Ausentismo_PRE!$B$3:$B$202,B8,Ausentismo_PRE!$E$3:$E$202,"Asistió")),"") | E8: =IFERROR(COUNTIFS(Consultas_PRE!$B$3:$B$202,B8,Consultas_PRE!$F$3:$F$202,"Sí",Consultas_PRE!$G$3:$G$202,"No")/COUNTIFS(Consultas_PRE!$B$3:$B$202,B8),"") | F8: 46286 | G8: =IFERROR(AVERAGEIFS(TPR_POST!$F$3:$F$202,TPR_POST!$B$3:$B$202,F8),"") | H8: =IFERROR(COUNTIFS(Ausentismo_POST!$B$3:$B$202,F8,Ausentismo_POST!$E$3:$E$202,"No asistió")/(COUNTIFS(Ausentismo_POST!$B$3:$B$202,F8,Ausentismo_POST!$E$3:$E$202,"No asistió")+COUNTIFS(Ausentismo_POST!$B$3:$B$202,F8,Ausentismo_POST!$E$3:$E$202,"Asistió")),"") | I8: =IFERROR(COUNTIFS(Consultas_POST!$B$3:$B$202,F8,Consultas_POST!$F$3:$F$202,"Sí",Consultas_POST!$G$3:$G$202,"No")/COUNTIFS(Consultas_POST!$B$3:$B$202,F8),"") | J8: =COUNTIFS(TPR_PRE!$B$3:$B$202,B8,TPR_PRE!$F$3:$F$202,">=0") | K8: =COUNTIFS(Ausentismo_PRE!$B$3:$B$202,B8,Ausentismo_PRE!$E$3:$E$202,"No asistió")+COUNTIFS(Ausentismo_PRE!$B$3:$B$202,B8,Ausentismo_PRE!$E$3:$E$202,"Asistió") | L8: =COUNTIFS(Consultas_PRE!$B$3:$B$202,B8) | M8: =COUNTIFS(TPR_POST!$B$3:$B$202,F8,TPR_POST!$F$3:$F$202,">=0") | N8: =COUNTIFS(Ausentismo_POST!$B$3:$B$202,F8,Ausentismo_POST!$E$3:$E$202,"No asistió")+COUNTIFS(Ausentismo_POST!$B$3:$B$202,F8,Ausentismo_POST!$E$3:$E$202,"Asistió") | O8: =COUNTIFS(Consultas_POST!$B$3:$B$202,F8) | P8: =IF(AND(J8>0,M8>0),"Sí","No") | Q8: =IF(AND(K8>0,N8>0),"Sí","No") | R8: =IF(AND(L8>0,O8>0),"Sí","No") | S8: =IF(WEEKDAY(B8)=WEEKDAY(F8),"Sí","No")
A9: 8 | B9: 46253 | C9: =IFERROR(AVERAGEIFS(TPR_PRE!$F$3:$F$202,TPR_PRE!$B$3:$B$202,B9),"") | D9: =IFERROR(COUNTIFS(Ausentismo_PRE!$B$3:$B$202,B9,Ausentismo_PRE!$E$3:$E$202,"No asistió")/(COUNTIFS(Ausentismo_PRE!$B$3:$B$202,B9,Ausentismo_PRE!$E$3:$E$202,"No asistió")+COUNTIFS(Ausentismo_PRE!$B$3:$B$202,B9,Ausentismo_PRE!$E$3:$E$202,"Asistió")),"") | E9: =IFERROR(COUNTIFS(Consultas_PRE!$B$3:$B$202,B9,Consultas_PRE!$F$3:$F$202,"Sí",Consultas_PRE!$G$3:$G$202,"No")/COUNTIFS(Consultas_PRE!$B$3:$B$202,B9),"") | F9: 46281 | G9: =IFERROR(AVERAGEIFS(TPR_POST!$F$3:$F$202,TPR_POST!$B$3:$B$202,F9),"") | H9: =IFERROR(COUNTIFS(Ausentismo_POST!$B$3:$B$202,F9,Ausentismo_POST!$E$3:$E$202,"No asistió")/(COUNTIFS(Ausentismo_POST!$B$3:$B$202,F9,Ausentismo_POST!$E$3:$E$202,"No asistió")+COUNTIFS(Ausentismo_POST!$B$3:$B$202,F9,Ausentismo_POST!$E$3:$E$202,"Asistió")),"") | I9: =IFERROR(COUNTIFS(Consultas_POST!$B$3:$B$202,F9,Consultas_POST!$F$3:$F$202,"Sí",Consultas_POST!$G$3:$G$202,"No")/COUNTIFS(Consultas_POST!$B$3:$B$202,F9),"") | J9: =COUNTIFS(TPR_PRE!$B$3:$B$202,B9,TPR_PRE!$F$3:$F$202,">=0") | K9: =COUNTIFS(Ausentismo_PRE!$B$3:$B$202,B9,Ausentismo_PRE!$E$3:$E$202,"No asistió")+COUNTIFS(Ausentismo_PRE!$B$3:$B$202,B9,Ausentismo_PRE!$E$3:$E$202,"Asistió") | L9: =COUNTIFS(Consultas_PRE!$B$3:$B$202,B9) | M9: =COUNTIFS(TPR_POST!$B$3:$B$202,F9,TPR_POST!$F$3:$F$202,">=0") | N9: =COUNTIFS(Ausentismo_POST!$B$3:$B$202,F9,Ausentismo_POST!$E$3:$E$202,"No asistió")+COUNTIFS(Ausentismo_POST!$B$3:$B$202,F9,Ausentismo_POST!$E$3:$E$202,"Asistió") | O9: =COUNTIFS(Consultas_POST!$B$3:$B$202,F9) | P9: =IF(AND(J9>0,M9>0),"Sí","No") | Q9: =IF(AND(K9>0,N9>0),"Sí","No") | R9: =IF(AND(L9>0,O9>0),"Sí","No") | S9: =IF(WEEKDAY(B9)=WEEKDAY(F9),"Sí","No")
A10: 9 | B10: 46255 | C10: =IFERROR(AVERAGEIFS(TPR_PRE!$F$3:$F$202,TPR_PRE!$B$3:$B$202,B10),"") | D10: =IFERROR(COUNTIFS(Ausentismo_PRE!$B$3:$B$202,B10,Ausentismo_PRE!$E$3:$E$202,"No asistió")/(COUNTIFS(Ausentismo_PRE!$B$3:$B$202,B10,Ausentismo_PRE!$E$3:$E$202,"No asistió")+COUNTIFS(Ausentismo_PRE!$B$3:$B$202,B10,Ausentismo_PRE!$E$3:$E$202,"Asistió")),"") | E10: =IFERROR(COUNTIFS(Consultas_PRE!$B$3:$B$202,B10,Consultas_PRE!$F$3:$F$202,"Sí",Consultas_PRE!$G$3:$G$202,"No")/COUNTIFS(Consultas_PRE!$B$3:$B$202,B10),"") | F10: 46283 | G10: =IFERROR(AVERAGEIFS(TPR_POST!$F$3:$F$202,TPR_POST!$B$3:$B$202,F10),"") | H10: =IFERROR(COUNTIFS(Ausentismo_POST!$B$3:$B$202,F10,Ausentismo_POST!$E$3:$E$202,"No asistió")/(COUNTIFS(Ausentismo_POST!$B$3:$B$202,F10,Ausentismo_POST!$E$3:$E$202,"No asistió")+COUNTIFS(Ausentismo_POST!$B$3:$B$202,F10,Ausentismo_POST!$E$3:$E$202,"Asistió")),"") | I10: =IFERROR(COUNTIFS(Consultas_POST!$B$3:$B$202,F10,Consultas_POST!$F$3:$F$202,"Sí",Consultas_POST!$G$3:$G$202,"No")/COUNTIFS(Consultas_POST!$B$3:$B$202,F10),"") | J10: =COUNTIFS(TPR_PRE!$B$3:$B$202,B10,TPR_PRE!$F$3:$F$202,">=0") | K10: =COUNTIFS(Ausentismo_PRE!$B$3:$B$202,B10,Ausentismo_PRE!$E$3:$E$202,"No asistió")+COUNTIFS(Ausentismo_PRE!$B$3:$B$202,B10,Ausentismo_PRE!$E$3:$E$202,"Asistió") | L10: =COUNTIFS(Consultas_PRE!$B$3:$B$202,B10) | M10: =COUNTIFS(TPR_POST!$B$3:$B$202,F10,TPR_POST!$F$3:$F$202,">=0") | N10: =COUNTIFS(Ausentismo_POST!$B$3:$B$202,F10,Ausentismo_POST!$E$3:$E$202,"No asistió")+COUNTIFS(Ausentismo_POST!$B$3:$B$202,F10,Ausentismo_POST!$E$3:$E$202,"Asistió") | O10: =COUNTIFS(Consultas_POST!$B$3:$B$202,F10) | P10: =IF(AND(J10>0,M10>0),"Sí","No") | Q10: =IF(AND(K10>0,N10>0),"Sí","No") | R10: =IF(AND(L10>0,O10>0),"Sí","No") | S10: =IF(WEEKDAY(B10)=WEEKDAY(F10),"Sí","No")
A11: 10 | B11: 46258 | C11: =IFERROR(AVERAGEIFS(TPR_PRE!$F$3:$F$202,TPR_PRE!$B$3:$B$202,B11),"") | D11: =IFERROR(COUNTIFS(Ausentismo_PRE!$B$3:$B$202,B11,Ausentismo_PRE!$E$3:$E$202,"No asistió")/(COUNTIFS(Ausentismo_PRE!$B$3:$B$202,B11,Ausentismo_PRE!$E$3:$E$202,"No asistió")+COUNTIFS(Ausentismo_PRE!$B$3:$B$202,B11,Ausentismo_PRE!$E$3:$E$202,"Asistió")),"") | E11: =IFERROR(COUNTIFS(Consultas_PRE!$B$3:$B$202,B11,Consultas_PRE!$F$3:$F$202,"Sí",Consultas_PRE!$G$3:$G$202,"No")/COUNTIFS(Consultas_PRE!$B$3:$B$202,B11),"") | F11: 46293 | G11: =IFERROR(AVERAGEIFS(TPR_POST!$F$3:$F$202,TPR_POST!$B$3:$B$202,F11),"") | H11: =IFERROR(COUNTIFS(Ausentismo_POST!$B$3:$B$202,F11,Ausentismo_POST!$E$3:$E$202,"No asistió")/(COUNTIFS(Ausentismo_POST!$B$3:$B$202,F11,Ausentismo_POST!$E$3:$E$202,"No asistió")+COUNTIFS(Ausentismo_POST!$B$3:$B$202,F11,Ausentismo_POST!$E$3:$E$202,"Asistió")),"") | I11: =IFERROR(COUNTIFS(Consultas_POST!$B$3:$B$202,F11,Consultas_POST!$F$3:$F$202,"Sí",Consultas_POST!$G$3:$G$202,"No")/COUNTIFS(Consultas_POST!$B$3:$B$202,F11),"") | J11: =COUNTIFS(TPR_PRE!$B$3:$B$202,B11,TPR_PRE!$F$3:$F$202,">=0") | K11: =COUNTIFS(Ausentismo_PRE!$B$3:$B$202,B11,Ausentismo_PRE!$E$3:$E$202,"No asistió")+COUNTIFS(Ausentismo_PRE!$B$3:$B$202,B11,Ausentismo_PRE!$E$3:$E$202,"Asistió") | L11: =COUNTIFS(Consultas_PRE!$B$3:$B$202,B11) | M11: =COUNTIFS(TPR_POST!$B$3:$B$202,F11,TPR_POST!$F$3:$F$202,">=0") | N11: =COUNTIFS(Ausentismo_POST!$B$3:$B$202,F11,Ausentismo_POST!$E$3:$E$202,"No asistió")+COUNTIFS(Ausentismo_POST!$B$3:$B$202,F11,Ausentismo_POST!$E$3:$E$202,"Asistió") | O11: =COUNTIFS(Consultas_POST!$B$3:$B$202,F11) | P11: =IF(AND(J11>0,M11>0),"Sí","No") | Q11: =IF(AND(K11>0,N11>0),"Sí","No") | R11: =IF(AND(L11>0,O11>0),"Sí","No") | S11: =IF(WEEKDAY(B11)=WEEKDAY(F11),"Sí","No")
A12: 11 | B12: 46260 | C12: =IFERROR(AVERAGEIFS(TPR_PRE!$F$3:$F$202,TPR_PRE!$B$3:$B$202,B12),"") | D12: =IFERROR(COUNTIFS(Ausentismo_PRE!$B$3:$B$202,B12,Ausentismo_PRE!$E$3:$E$202,"No asistió")/(COUNTIFS(Ausentismo_PRE!$B$3:$B$202,B12,Ausentismo_PRE!$E$3:$E$202,"No asistió")+COUNTIFS(Ausentismo_PRE!$B$3:$B$202,B12,Ausentismo_PRE!$E$3:$E$202,"Asistió")),"") | E12: =IFERROR(COUNTIFS(Consultas_PRE!$B$3:$B$202,B12,Consultas_PRE!$F$3:$F$202,"Sí",Consultas_PRE!$G$3:$G$202,"No")/COUNTIFS(Consultas_PRE!$B$3:$B$202,B12),"") | F12: 46288 | G12: =IFERROR(AVERAGEIFS(TPR_POST!$F$3:$F$202,TPR_POST!$B$3:$B$202,F12),"") | H12: =IFERROR(COUNTIFS(Ausentismo_POST!$B$3:$B$202,F12,Ausentismo_POST!$E$3:$E$202,"No asistió")/(COUNTIFS(Ausentismo_POST!$B$3:$B$202,F12,Ausentismo_POST!$E$3:$E$202,"No asistió")+COUNTIFS(Ausentismo_POST!$B$3:$B$202,F12,Ausentismo_POST!$E$3:$E$202,"Asistió")),"") | I12: =IFERROR(COUNTIFS(Consultas_POST!$B$3:$B$202,F12,Consultas_POST!$F$3:$F$202,"Sí",Consultas_POST!$G$3:$G$202,"No")/COUNTIFS(Consultas_POST!$B$3:$B$202,F12),"") | J12: =COUNTIFS(TPR_PRE!$B$3:$B$202,B12,TPR_PRE!$F$3:$F$202,">=0") | K12: =COUNTIFS(Ausentismo_PRE!$B$3:$B$202,B12,Ausentismo_PRE!$E$3:$E$202,"No asistió")+COUNTIFS(Ausentismo_PRE!$B$3:$B$202,B12,Ausentismo_PRE!$E$3:$E$202,"Asistió") | L12: =COUNTIFS(Consultas_PRE!$B$3:$B$202,B12) | M12: =COUNTIFS(TPR_POST!$B$3:$B$202,F12,TPR_POST!$F$3:$F$202,">=0") | N12: =COUNTIFS(Ausentismo_POST!$B$3:$B$202,F12,Ausentismo_POST!$E$3:$E$202,"No asistió")+COUNTIFS(Ausentismo_POST!$B$3:$B$202,F12,Ausentismo_POST!$E$3:$E$202,"Asistió") | O12: =COUNTIFS(Consultas_POST!$B$3:$B$202,F12) | P12: =IF(AND(J12>0,M12>0),"Sí","No") | Q12: =IF(AND(K12>0,N12>0),"Sí","No") | R12: =IF(AND(L12>0,O12>0),"Sí","No") | S12: =IF(WEEKDAY(B12)=WEEKDAY(F12),"Sí","No")
A13: 12 | B13: 46262 | C13: =IFERROR(AVERAGEIFS(TPR_PRE!$F$3:$F$202,TPR_PRE!$B$3:$B$202,B13),"") | D13: =IFERROR(COUNTIFS(Ausentismo_PRE!$B$3:$B$202,B13,Ausentismo_PRE!$E$3:$E$202,"No asistió")/(COUNTIFS(Ausentismo_PRE!$B$3:$B$202,B13,Ausentismo_PRE!$E$3:$E$202,"No asistió")+COUNTIFS(Ausentismo_PRE!$B$3:$B$202,B13,Ausentismo_PRE!$E$3:$E$202,"Asistió")),"") | E13: =IFERROR(COUNTIFS(Consultas_PRE!$B$3:$B$202,B13,Consultas_PRE!$F$3:$F$202,"Sí",Consultas_PRE!$G$3:$G$202,"No")/COUNTIFS(Consultas_PRE!$B$3:$B$202,B13),"") | F13: 46290 | G13: =IFERROR(AVERAGEIFS(TPR_POST!$F$3:$F$202,TPR_POST!$B$3:$B$202,F13),"") | H13: =IFERROR(COUNTIFS(Ausentismo_POST!$B$3:$B$202,F13,Ausentismo_POST!$E$3:$E$202,"No asistió")/(COUNTIFS(Ausentismo_POST!$B$3:$B$202,F13,Ausentismo_POST!$E$3:$E$202,"No asistió")+COUNTIFS(Ausentismo_POST!$B$3:$B$202,F13,Ausentismo_POST!$E$3:$E$202,"Asistió")),"") | I13: =IFERROR(COUNTIFS(Consultas_POST!$B$3:$B$202,F13,Consultas_POST!$F$3:$F$202,"Sí",Consultas_POST!$G$3:$G$202,"No")/COUNTIFS(Consultas_POST!$B$3:$B$202,F13),"") | J13: =COUNTIFS(TPR_PRE!$B$3:$B$202,B13,TPR_PRE!$F$3:$F$202,">=0") | K13: =COUNTIFS(Ausentismo_PRE!$B$3:$B$202,B13,Ausentismo_PRE!$E$3:$E$202,"No asistió")+COUNTIFS(Ausentismo_PRE!$B$3:$B$202,B13,Ausentismo_PRE!$E$3:$E$202,"Asistió") | L13: =COUNTIFS(Consultas_PRE!$B$3:$B$202,B13) | M13: =COUNTIFS(TPR_POST!$B$3:$B$202,F13,TPR_POST!$F$3:$F$202,">=0") | N13: =COUNTIFS(Ausentismo_POST!$B$3:$B$202,F13,Ausentismo_POST!$E$3:$E$202,"No asistió")+COUNTIFS(Ausentismo_POST!$B$3:$B$202,F13,Ausentismo_POST!$E$3:$E$202,"Asistió") | O13: =COUNTIFS(Consultas_POST!$B$3:$B$202,F13) | P13: =IF(AND(J13>0,M13>0),"Sí","No") | Q13: =IF(AND(K13>0,N13>0),"Sí","No") | R13: =IF(AND(L13>0,O13>0),"Sí","No") | S13: =IF(WEEKDAY(B13)=WEEKDAY(F13),"Sí","No")
A14: 13 | B14: 46265 | C14: =IFERROR(AVERAGEIFS(TPR_PRE!$F$3:$F$202,TPR_PRE!$B$3:$B$202,B14),"") | D14: =IFERROR(COUNTIFS(Ausentismo_PRE!$B$3:$B$202,B14,Ausentismo_PRE!$E$3:$E$202,"No asistió")/(COUNTIFS(Ausentismo_PRE!$B$3:$B$202,B14,Ausentismo_PRE!$E$3:$E$202,"No asistió")+COUNTIFS(Ausentismo_PRE!$B$3:$B$202,B14,Ausentismo_PRE!$E$3:$E$202,"Asistió")),"") | E14: =IFERROR(COUNTIFS(Consultas_PRE!$B$3:$B$202,B14,Consultas_PRE!$F$3:$F$202,"Sí",Consultas_PRE!$G$3:$G$202,"No")/COUNTIFS(Consultas_PRE!$B$3:$B$202,B14),"") | F14: 46295 | G14: =IFERROR(AVERAGEIFS(TPR_POST!$F$3:$F$202,TPR_POST!$B$3:$B$202,F14),"") | H14: =IFERROR(COUNTIFS(Ausentismo_POST!$B$3:$B$202,F14,Ausentismo_POST!$E$3:$E$202,"No asistió")/(COUNTIFS(Ausentismo_POST!$B$3:$B$202,F14,Ausentismo_POST!$E$3:$E$202,"No asistió")+COUNTIFS(Ausentismo_POST!$B$3:$B$202,F14,Ausentismo_POST!$E$3:$E$202,"Asistió")),"") | I14: =IFERROR(COUNTIFS(Consultas_POST!$B$3:$B$202,F14,Consultas_POST!$F$3:$F$202,"Sí",Consultas_POST!$G$3:$G$202,"No")/COUNTIFS(Consultas_POST!$B$3:$B$202,F14),"") | J14: =COUNTIFS(TPR_PRE!$B$3:$B$202,B14,TPR_PRE!$F$3:$F$202,">=0") | K14: =COUNTIFS(Ausentismo_PRE!$B$3:$B$202,B14,Ausentismo_PRE!$E$3:$E$202,"No asistió")+COUNTIFS(Ausentismo_PRE!$B$3:$B$202,B14,Ausentismo_PRE!$E$3:$E$202,"Asistió") | L14: =COUNTIFS(Consultas_PRE!$B$3:$B$202,B14) | M14: =COUNTIFS(TPR_POST!$B$3:$B$202,F14,TPR_POST!$F$3:$F$202,">=0") | N14: =COUNTIFS(Ausentismo_POST!$B$3:$B$202,F14,Ausentismo_POST!$E$3:$E$202,"No asistió")+COUNTIFS(Ausentismo_POST!$B$3:$B$202,F14,Ausentismo_POST!$E$3:$E$202,"Asistió") | O14: =COUNTIFS(Consultas_POST!$B$3:$B$202,F14) | P14: =IF(AND(J14>0,M14>0),"Sí","No") | Q14: =IF(AND(K14>0,N14>0),"Sí","No") | R14: =IF(AND(L14>0,O14>0),"Sí","No") | S14: =IF(WEEKDAY(B14)=WEEKDAY(F14),"Sí","No")
A16: Esta hoja se calcula automáticamente a partir de las hojas TPR/Ausentismo/Consultas PRE y POST. No editar manualmente.

Sheet Bitacora_Sesiones
A1: Etapa | B1: Par | C1: Fecha | D1: Horario de observación | E1: Observador(es) | F1: Registros | G1: Citas elegibles | H1: Consultas | I1: ¿Hubo atención normal? | J1: Incidencias (feriado, cierre, cambio de personal, falla del sistema)
A2: PRE | B2: 1 | C2: =Sesiones!B2 | F2: =Sesiones!J2 | G2: =Sesiones!K2 | H2: =Sesiones!L2
A3: PRE | B3: 2 | C3: =Sesiones!B3 | F3: =Sesiones!J3 | G3: =Sesiones!K3 | H3: =Sesiones!L3
A4: PRE | B4: 3 | C4: =Sesiones!B4 | F4: =Sesiones!J4 | G4: =Sesiones!K4 | H4: =Sesiones!L4
A5: PRE | B5: 4 | C5: =Sesiones!B5 | F5: =Sesiones!J5 | G5: =Sesiones!K5 | H5: =Sesiones!L5
A6: PRE | B6: 5 | C6: =Sesiones!B6 | F6: =Sesiones!J6 | G6: =Sesiones!K6 | H6: =Sesiones!L6
A7: PRE | B7: 6 | C7: =Sesiones!B7 | F7: =Sesiones!J7 | G7: =Sesiones!K7 | H7: =Sesiones!L7
A8: PRE | B8: 7 | C8: =Sesiones!B8 | F8: =Sesiones!J8 | G8: =Sesiones!K8 | H8: =Sesiones!L8
A9: PRE | B9: 8 | C9: =Sesiones!B9 | F9: =Sesiones!J9 | G9: =Sesiones!K9 | H9: =Sesiones!L9
A10: PRE | B10: 9 | C10: =Sesiones!B10 | F10: =Sesiones!J10 | G10: =Sesiones!K10 | H10: =Sesiones!L10
A11: PRE | B11: 10 | C11: =Sesiones!B11 | F11: =Sesiones!J11 | G11: =Sesiones!K11 | H11: =Sesiones!L11
A12: PRE | B12: 11 | C12: =Sesiones!B12 | F12: =Sesiones!J12 | G12: =Sesiones!K12 | H12: =Sesiones!L12
A13: PRE | B13: 12 | C13: =Sesiones!B13 | F13: =Sesiones!J13 | G13: =Sesiones!K13 | H13: =Sesiones!L13
A14: PRE | B14: 13 | C14: =Sesiones!B14 | F14: =Sesiones!J14 | G14: =Sesiones!K14 | H14: =Sesiones!L14
A15: POST | B15: 1 | C15: =Sesiones!F2 | F15: =Sesiones!M2 | G15: =Sesiones!N2 | H15: =Sesiones!O2
A16: POST | B16: 2 | C16: =Sesiones!F3 | F16: =Sesiones!M3 | G16: =Sesiones!N3 | H16: =Sesiones!O3
A17: POST | B17: 3 | C17: =Sesiones!F4 | F17: =Sesiones!M4 | G17: =Sesiones!N4 | H17: =Sesiones!O4
A18: POST | B18: 4 | C18: =Sesiones!F5 | F18: =Sesiones!M5 | G18: =Sesiones!N5 | H18: =Sesiones!O5
A19: POST | B19: 5 | C19: =Sesiones!F6 | F19: =Sesiones!M6 | G19: =Sesiones!N6 | H19: =Sesiones!O6
A20: POST | B20: 6 | C20: =Sesiones!F7 | F20: =Sesiones!M7 | G20: =Sesiones!N7 | H20: =Sesiones!O7
A21: POST | B21: 7 | C21: =Sesiones!F8 | F21: =Sesiones!M8 | G21: =Sesiones!N8 | H21: =Sesiones!O8
A22: POST | B22: 8 | C22: =Sesiones!F9 | F22: =Sesiones!M9 | G22: =Sesiones!N9 | H22: =Sesiones!O9
A23: POST | B23: 9 | C23: =Sesiones!F10 | F23: =Sesiones!M10 | G23: =Sesiones!N10 | H23: =Sesiones!O10
A24: POST | B24: 10 | C24: =Sesiones!F11 | F24: =Sesiones!M11 | G24: =Sesiones!N11 | H24: =Sesiones!O11
A25: POST | B25: 11 | C25: =Sesiones!F12 | F25: =Sesiones!M12 | G25: =Sesiones!N12 | H25: =Sesiones!O12
A26: POST | B26: 12 | C26: =Sesiones!F13 | F26: =Sesiones!M13 | G26: =Sesiones!N13 | H26: =Sesiones!O13
A27: POST | B27: 13 | C27: =Sesiones!F14 | F27: =Sesiones!M14 | G27: =Sesiones!N14 | H27: =Sesiones!O14

Sheet Resumen_PRE_POST
A1: Indicador | B1: PRE (promedio 13 sesiones) | C1: POST (promedio 13 sesiones) | D1: Diferencia | E1: Dirección esperada | F1: Valor global PRE (todos los eventos) | G1: Valor global POST (todos los eventos) | H1: Pares válidos
A2: Tiempo Promedio de Registro (TPR, min) | B2: =IFERROR(AVERAGE(Sesiones!C2:C14),"") | C2: =IFERROR(AVERAGE(Sesiones!G2:G14),"") | D2: =IFERROR(C2-B2,"") | E2: PRE > POST (se espera reducción) | F2: =IFERROR(AVERAGE(TPR_PRE!F3:F202),"") | G2: =IFERROR(AVERAGE(TPR_POST!F3:F202),"") | H2: =COUNTIF(Sesiones!P2:P14,"Sí")
A3: Tasa de Ausentismo (%) | B3: =IFERROR(AVERAGE(Sesiones!D2:D14),"") | C3: =IFERROR(AVERAGE(Sesiones!H2:H14),"") | D3: =IFERROR(C3-B3,"") | E3: PRE > POST (se espera reducción) | F3: =IFERROR(COUNTIF(Ausentismo_PRE!E3:E202,"No asistió")/(COUNTIF(Ausentismo_PRE!E3:E202,"No asistió")+COUNTIF(Ausentismo_PRE!E3:E202,"Asistió")),"") | G3: =IFERROR(COUNTIF(Ausentismo_POST!E3:E202,"No asistió")/(COUNTIF(Ausentismo_POST!E3:E202,"No asistió")+COUNTIF(Ausentismo_POST!E3:E202,"Asistió")),"") | H3: =COUNTIF(Sesiones!Q2:Q14,"Sí")
A4: Nivel de Consultas Atendidas (%) | B4: =IFERROR(AVERAGE(Sesiones!E2:E14),"") | C4: =IFERROR(AVERAGE(Sesiones!I2:I14),"") | D4: =IFERROR(C4-B4,"") | E4: POST > PRE (se espera aumento) | F4: =IFERROR(COUNTIFS(Consultas_PRE!F3:F202,"Sí",Consultas_PRE!G3:G202,"No")/COUNT(Consultas_PRE!B3:B202),"") | G4: =IFERROR(COUNTIFS(Consultas_POST!F3:F202,"Sí",Consultas_POST!G3:G202,"No")/COUNT(Consultas_POST!B3:B202),"") | H4: =COUNTIF(Sesiones!R2:R14,"Sí")
A6: Los valores PRE y POST (columnas B y C) son el promedio de los valores por sesión; las columnas F y G calculan el indicador sobre el total de eventos de cada etapa. El contraste estadístico se realiza en SPSS con los pares válidos de la hoja Sesiones.
A7: Los valores se calculan automáticamente a partir de la hoja Sesiones, que a su vez se alimenta de los registros reales ingresados en las hojas PRE/POST.

Sheet SPSS_Pares
A1: par | B1: fecha_pre | C1: fecha_post | D1: mismo_dia | E1: tpr_pre | F1: tpr_post | G1: ta_pre | H1: ta_post | I1: nca_pre | J1: nca_post
A2: 1 | B2: =TEXT(Sesiones!B2,"dd/mm/yyyy") | C2: =TEXT(Sesiones!F2,"dd/mm/yyyy") | D2: =IF(Sesiones!S2="Sí",1,0) | E2: =IF(Sesiones!P2="Sí",ROUND(Sesiones!C2,2),"") | F2: =IF(Sesiones!P2="Sí",ROUND(Sesiones!G2,2),"") | G2: =IF(Sesiones!Q2="Sí",ROUND(Sesiones!D2*100,2),"") | H2: =IF(Sesiones!Q2="Sí",ROUND(Sesiones!H2*100,2),"") | I2: =IF(Sesiones!R2="Sí",ROUND(Sesiones!E2*100,2),"") | J2: =IF(Sesiones!R2="Sí",ROUND(Sesiones!I2*100,2),"")
A3: 2 | B3: =TEXT(Sesiones!B3,"dd/mm/yyyy") | C3: =TEXT(Sesiones!F3,"dd/mm/yyyy") | D3: =IF(Sesiones!S3="Sí",1,0) | E3: =IF(Sesiones!P3="Sí",ROUND(Sesiones!C3,2),"") | F3: =IF(Sesiones!P3="Sí",ROUND(Sesiones!G3,2),"") | G3: =IF(Sesiones!Q3="Sí",ROUND(Sesiones!D3*100,2),"") | H3: =IF(Sesiones!Q3="Sí",ROUND(Sesiones!H3*100,2),"") | I3: =IF(Sesiones!R3="Sí",ROUND(Sesiones!E3*100,2),"") | J3: =IF(Sesiones!R3="Sí",ROUND(Sesiones!I3*100,2),"")
A4: 3 | B4: =TEXT(Sesiones!B4,"dd/mm/yyyy") | C4: =TEXT(Sesiones!F4,"dd/mm/yyyy") | D4: =IF(Sesiones!S4="Sí",1,0) | E4: =IF(Sesiones!P4="Sí",ROUND(Sesiones!C4,2),"") | F4: =IF(Sesiones!P4="Sí",ROUND(Sesiones!G4,2),"") | G4: =IF(Sesiones!Q4="Sí",ROUND(Sesiones!D4*100,2),"") | H4: =IF(Sesiones!Q4="Sí",ROUND(Sesiones!H4*100,2),"") | I4: =IF(Sesiones!R4="Sí",ROUND(Sesiones!E4*100,2),"") | J4: =IF(Sesiones!R4="Sí",ROUND(Sesiones!I4*100,2),"")
