Workbook

Sheet LEER_PRIMERO
A1: DATOS SIMULADOS — SOLO PARA PRÁCTICA
A2: Este archivo fue generado automáticamente con números aleatorios para aprender a usar el instrumento y el análisis en SPSS.
A3: NO contiene datos reales de la fundación. NO debe usarse, copiarse ni citarse en la tesis ni en ningún documento de la investigación.
A4: Presentar datos simulados como reales constituye fabricación de datos (falta grave según el Código de Ética en Investigación de la UCV).
A5: Para la tesis se usa Instrumento_v6_PRE_POST.xlsx, vacío, completado únicamente con registros reales.
A6: Semilla aleatoria: 2026. Códigos de paciente: SIM-01 a SIM-30.

Sheet Listas
A1: FechasPRE | B1: FechasPOST | C1: SiNo | D1: EstadoCita | E1: Categoria | F1: CanalPRE | G1: Sexo | H1: EstadoPaciente | I1: ResultadoVI
A2: 46237 | B2: 46267 | C2: Sí | D2: Asistió | E2: Citas | F2: Presencial | G2: M | H2: Activo | I2: Implementado
A3: 46239 | B3: 46269 | C3: No | D3: No asistió | E3: Horarios | F3: Telefónico | G3: F | H3: Inactivo | I3: No implementado
A4: 46241 | B4: 46272 | D4: Cancelada | E4: Información institucional | F4: WhatsApp institucional
A5: 46244 | B5: 46274 | D5: Reprogramada | E5: Requisitos
A6: 46246 | B6: 46276 | E6: Ubicación
A7: 46248 | B7: 46279 | E7: Seguimiento administrativo
A8: 46251 | B8: 46281 | E8: Otro
A9: 46253 | B9: 46283
A10: 46255 | B10: 46286
A11: 46258 | B11: 46288
A12: 46260 | B12: 46290
A13: 46262 | B13: 46293
A14: 46265 | B14: 46295

Sheet Configuracion
A1: CONFIGURACIÓN DEL ESTUDIO — ARCHIVO CON DATOS SIMULADOS (NO USAR EN LA TESIS)
A2: Código de estudio: | B2: SWC-FO-2026 (Sistema Web con Chatbot - Fundación Oncológica - 2026)
A3: Título: | B3: Sistema web con chatbot para la gestión de pacientes en una fundación oncológica privada de Lima, 2026
A4: Diseño: | B4: Pre-experimental de un solo grupo, con pretest y postest, comparados mediante 13 sesiones equivalentes
A5: Fechas PRETEST (lun/mié/vie): | B5: 03/08/2026, 05/08/2026, 07/08/2026, 10/08/2026, 12/08/2026, 14/08/2026, 17/08/2026, 19/08/2026, 21/08/2026, 24/08/2026, 26/08/2026, 28/08/2026, 31/08/2026
A6: Fechas POSTEST (lun/mié/vie): | B6: 02/09/2026, 04/09/2026, 07/09/2026, 09/09/2026, 11/09/2026, 14/09/2026, 16/09/2026, 18/09/2026, 21/09/2026, 23/09/2026, 25/09/2026, 28/09/2026, 30/09/2026
A7: Unidad de análisis - TPR: | B7: Cada proceso de registro de paciente efectivamente ejecutado
A8: Unidad de análisis - Ausentismo: | B8: Cada cita médica programada elegible (se excluyen citas canceladas o reprogramadas con anticipación)
A9: Unidad de análisis - Consultas: | B9: Cada consulta administrativa recibida (canales habituales en el pretest; chatbot en el postest)
A10: Fórmula TPR: | B10: TPR = (Σ tiempo de cada registro) / (N.° de registros), en minutos
A11: Fórmula Tasa de Ausentismo: | B11: TA = (N.° de citas no asistidas sin previo aviso / N.° de citas programadas elegibles) x 100
A12: Fórmula Nivel de Consultas Atendidas: | B12: NCA = (N.° de consultas resueltas en el primer contacto y no derivadas / N.° de consultas recibidas) x 100
A13: Criterios de inclusión: | B13: Pacientes activos de la fundación oncológica durante el período de estudio, mayores de edad, con al menos una cita programada en la institución en dicho período y que acepten participar mediante consentimiento informado.
... A15: Regla de calidad de datos: | B15: Registrar únicamente los eventos que realmente ocurrieron cada sesión. No completar filas artificiales para alcanzar un número fijo de registros, citas o consultas.
A17: CÓMO USAR ESTE ARCHIVO
A18: 1. Use la hoja Pacientes para registrar a los 30 participantes (código, edad, sexo). Si aparece un paciente nuevo durante el postest que no estaba en la lista original, agréguelo al final.
A19: 2. En cada hoja PRE/POST (TPR, Ausentismo, Consultas), agregue una fila por cada evento real (registro, cita o consulta) que haya ocurrido, seleccionando la fecha de la lista desplegable. No es necesario llenar un número fijo de filas por sesión.
A20: 3. Las celdas en amarillo son las que debe completar con datos reales. Las columnas de fecha y las categóricas tienen lista desplegable para evitar errores de escritura.
A21: 4. La hoja Sesiones calcula automáticamente el valor de cada indicador por sesión (13 PRE y 13 POST) a partir de lo que usted haya registrado. No edite esa hoja manualmente.
A22: 5. La hoja Resumen_PRE_POST muestra el promedio general de cada indicador; se actualiza sola.
A24: REGLAS DE REGISTRO (versión 3)
A25: Consulta resuelta: | B25: Se marca "Sí" en la columna F solo si el paciente obtuvo la información solicitada en el primer contacto y no necesitó volver a comunicarse por el mismo motivo. Se aplica igual en el pretest y en el postest.
A26: Consulta derivada: | B26: Se marca "Sí" en la columna G si la consulta tuvo que pasarse a otra persona o área para completarse. Una consulta derivada no cuenta como resuelta para el NCA.
A27: Aviso previo (ausentismo): | B27: Si el paciente avisó antes de la fecha, la cita se registra como "Cancelada" o "Reprogramada" y no entra al cálculo. "No asistió" se usa solo para inasistencias sin aviso.
A28: Sesiones sin eventos: | B28: Si una sesión no tiene eventos de un indicador, su valor queda vacío y el par se marca como no válido en la hoja Sesiones; se excluye del contraste y se informa el número de pares válidos.
A29: Emparejamiento de sesiones: | B29: Por día de la semana y orden de aparición (1.er lunes PRE con 1.er lunes POST, etc.). Pares 1 a 12 con el mismo día; el par 13 une las últimas sesiones (lun 31/08 – mié 30/09) y se excluye en el análisis de sensibilidad. Ver columna S de la hoja Sesiones.
A30: Variable independiente: | B30: Registrar en la hoja Verificacion_VI la verificación de cada módulo del sistema antes de iniciar el postest.
A31: Control de calidad: | B31: Columna "Control de calidad" en cada hoja de registro y resumen en la hoja Control_Calidad. Consentimientos y bitácora en sus hojas respectivas.
A32: Exportación a SPSS: | B32: La hoja SPSS_Pares arma automáticamente los 13 pares para el archivo Analisis_SPSS.sps.

Sheet Pacientes
A1: Código | B1: Edad | C1: Sexo | D1: Estado | E1: Participó en la muestra original (30)
A2: SIM-01 | B2: 73 | C2: M | D2: Activo | E2: Sí
A3: SIM-02 | B3: 31 | C3: F | D3: Activo | E3: Sí
A4: SIM-03 | B4: 48 | C4: M | D4: Activo | E4: Sí
A5: SIM-04 | B5: 34 | C5: M | D5: Activo | E5: Sí
A6: SIM-05 | B6: 62 | C6: M | D6: Activo | E6: Sí
A7: SIM-06 | B7: 72 | C7: F | D7: Activo | E7: Sí
A8: SIM-07 | B8: 65 | C8: F | D8: Activo | E8: Sí
A9: SIM-08 | B9: 66 | C9: M | D9: Activo | E9: Sí
A10: SIM-09 | B10: 73 | C10: F | D10: Activo | E10: Sí
A11: SIM-10 | B11: 35 | C11: M | D11: Activo | E11: Sí
A12: SIM-11 | B12: 38 | C12: F | D12: Activo | E12: Sí
A13: SIM-12 | B13: 67 | C13: F | D13: Activo | E13: Sí
... A31: SIM-30 | B31: 63 | C31: M | D31: Activo | E31: Sí
E32: No (nuevo)
E33: No (nuevo)
E34: No (nuevo)
E35: No (nuevo)
E36: No (nuevo)
E37: No (nuevo)
E38: No (nuevo)
E39: No (nuevo)
E40: No (nuevo)
E41: No (nuevo)
E42: No (nuevo)
E43: No (nuevo)
... E46: No (nuevo)

Sheet Consentimientos
A1: Código del paciente | B1: Firmó el consentimiento | C1: Fecha de firma | D1: Retiró su consentimiento | E1: Fecha de retiro | F1: Observación | G1: Control
A2: =IF(Pacientes!A2="","",Pacientes!A2) | B2: Sí | C2: 46234 | D2: No | F2: SIMULADO | G2: =IF(A2="","",IF(B2<>"Sí","Sin consentimiento: excluir sus registros",IF(C2="","Falta fecha de firma",IF(C2>DATE(2026,8,3),"Firmado después del inicio del pretest (declarar)",IF(D2="Sí","Retirado: excluir desde la fecha de retiro","OK")))))
A3: =IF(Pacientes!A3="","",Pacientes!A3) | B3: Sí | C3: 46231 | D3: No | F3: SIMULADO | G3: =IF(A3="","",IF(B3<>"Sí","Sin consentimiento: excluir sus registros",IF(C3="","Falta fecha de firma",IF(C3>DATE(2026,8,3),"Firmado después del inicio del pretest (declarar)",IF(D3="Sí","Retirado: excluir desde la fecha de retiro","OK")))))
A4: =IF(Pacientes!A4="","",Pacientes!A4) | B4: Sí | C4: 46234 | D4: No | F4: SIMULADO | G4: =IF(A4="","",IF(B4<>"Sí","Sin consentimiento: excluir sus registros",IF(C4="","Falta fecha de firma",IF(C4>DATE(2026,8,3),"Firmado después del inicio del pretest (declarar)",IF(D4="Sí","Retirado: excluir desde la fecha de retiro","OK")))))
A5: =IF(Pacientes!A5="","",Pacientes!A5) | B5: Sí | C5: 46234 | D5: No | F5: SIMULADO | G5: =IF(A5="","",IF(B5<>"Sí","Sin consentimiento: excluir sus registros",IF(C5="","Falta fecha de firma",IF(C5>DATE(2026,8,3),"Firmado después del inicio del pretest (declarar)",IF(D5="Sí","Retirado: excluir desde la fecha de retiro","OK")))))
A6: =IF(Pacientes!A6="","",Pacientes!A6) | B6: Sí | C6: 46234 | D6: No | F6: SIMULADO | G6: =IF(A6="","",IF(B6<>"Sí","Sin consentimiento: excluir sus registros",IF(C6="","Falta fecha de firma",IF(C6>DATE(2026,8,3),"Firmado después del inicio del pretest (declarar)",IF(D6="Sí","Retirado: excluir desde la fecha de retiro","OK")))))
A7: =IF(Pacientes!A7="","",Pacientes!A7) | B7: Sí | C7: 46233 | D7: No | F7: SIMULADO | G7: =IF(A7="","",IF(B7<>"Sí","Sin consentimiento: excluir sus registros",IF(C7="","Falta fecha de firma",IF(C7>DATE(2026,8,3),"Firmado después del inicio del pretest (declarar)",IF(D7="Sí","Retirado: excluir desde la fecha de retiro","OK")))))
A8: =IF(Pacientes!A8="","",Pacientes!A8) | B8: Sí | C8: 46232 | D8: No | F8: SIMULADO | G8: =IF(A8="","",IF(B8<>"Sí","Sin consentimiento: excluir sus registros",IF(C8="","Falta fecha de firma",IF(C8>DATE(2026,8,3),"Firmado después del inicio del pretest (declarar)",IF(D8="Sí","Retirado: excluir desde la fecha de retiro","OK")))))
A9: =IF(Pacientes!A9="","",Pacientes!A9) | B9: Sí | C9: 46233 | D9: No | F9: SIMULADO | G9: =IF(A9="","",IF(B9<>"Sí","Sin consentimiento: excluir sus registros",IF(C9="","Falta fecha de firma",IF(C9>DATE(2026,8,3),"Firmado después del inicio del pretest (declarar)",IF(D9="Sí","Retirado: excluir desde la fecha de retiro","OK")))))
A10: =IF(Pacientes!A10="","",Pacientes!A10) | B10: Sí | C10: 46231 | D10: No | F10: SIMULADO | G10: =IF(A10="","",IF(B10<>"Sí","Sin consentimiento: excluir sus registros",IF(C10="","Falta fecha de firma",IF(C10>DATE(2026,8,3),"Firmado después del inicio del pretest (declarar)",IF(D10="Sí","Retirado: excluir desde la fecha de retiro","OK")))))
A11: =IF(Pacientes!A11="","",Pacientes!A11) | B11: Sí | C11: 46231 | D11: No | F11: SIMULADO | G11: =IF(A11="","",IF(B11<>"Sí","Sin consentimiento: excluir sus registros",IF(C11="","Falta fecha de firma",IF(C11>DATE(2026,8,3),"Firmado después del inicio del pretest (declarar)",IF(D11="Sí","Retirado: excluir desde la fecha de retiro","OK")))))
A12: =IF(Pacientes!A12="","",Pacientes!A12) | B12: Sí | C12: 46232 | D12: No | F12: SIMULADO | G12: =IF(A12="","",IF(B12<>"Sí","Sin consentimiento: excluir sus registros",IF(C12="","Falta fecha de firma",IF(C12>DATE(2026,8,3),"Firmado después del inicio del pretest (declarar)",IF(D12="Sí","Retirado: excluir desde la fecha de retiro","OK")))))
A13: =IF(Pacientes!A13="","",Pacientes!A13) | B13: Sí | C13: 46234 | D13: No | F13: SIMULADO | G13: =IF(A13="","",IF(B13<>"Sí","Sin consentimiento: excluir sus registros",IF(C13="","Falta fecha de firma",IF(C13>DATE(2026,8,3),"Firmado después del inicio del pretest (declarar)",IF(D13="Sí","Retirado: excluir desde la fecha de retiro","OK")))))
... A31: =IF(Pacientes!A31="","",Pacientes!A31) | B31: Sí | C31: 46231 | D31: No | F31: SIMULADO | G31: =IF(A31="","",IF(B31<>"Sí","Sin consentimiento: excluir sus registros",IF(C31="","Falta fecha de firma",IF(C31>DATE(2026,8,3),"Firmado después del inicio del pretest (declarar)",IF(D31="Sí","Retirado: excluir desde la fecha de retiro","OK")))))
A32: =IF(Pacientes!A32="","",Pacientes!A32) | G32: =IF(A32="","",IF(B32<>"Sí","Sin consentimiento: excluir sus registros",IF(C32="","Falta fecha de firma",IF(C32>DATE(2026,8,3),"Firmado después del inicio del pretest (declarar)",IF(D32="Sí","Retirado: excluir desde la fecha de retiro","OK")))))
A33: =IF(Pacientes!A33="","",Pacientes!A33) | G33: =IF(A33="","",IF(B33<>"Sí","Sin consentimiento: excluir sus registros",IF(C33="","Falta fecha de firma",IF(C33>DATE(2026,8,3),"Firmado después del inicio del pretest (declarar)",IF(D33="Sí","Retirado: excluir desde la fecha de retiro","OK")))))
A34: =IF(Pacientes!A34="","",Pacientes!A34) | G34: =IF(A34="","",IF(B34<>"Sí","Sin consentimiento: excluir sus registros",IF(C34="","Falta fecha de firma",IF(C34>DATE(2026,8,3),"Firmado después del inicio del pretest (declarar)",IF(D34="Sí","Retirado: excluir desde la fecha de retiro","OK")))))
A35: =IF(Pacientes!A35="","",Pacientes!A35) | G35: =IF(A35="","",IF(B35<>"Sí","Sin consentimiento: excluir sus registros",IF(C35="","Falta fecha de firma",IF(C35>DATE(2026,8,3),"Firmado después del inicio del pretest (declarar)",IF(D35="Sí","Retirado: excluir desde la fecha de retiro","OK")))))
A36: =IF(Pacientes!A36="","",Pacientes!A36) | G36: =IF(A36="","",IF(B36<>"Sí","Sin consentimiento: excluir sus registros",IF(C36="","Falta fecha de firma",IF(C36>DATE(2026,8,3),"Firmado después del inicio del pretest (declarar)",IF(D36="Sí","Retirado: excluir desde la fecha de retiro","OK")))))
A37: =IF(Pacientes!A37="","",Pacientes!A37) | G37: =IF(A37="","",IF(B37<>"Sí","Sin consentimiento: excluir sus registros",IF(C37="","Falta fecha de firma",IF(C37>DATE(2026,8,3),"Firmado después del inicio del pretest (declarar)",IF(D37="Sí","Retirado: excluir desde la fecha de retiro","OK")))))
A38: =IF(Pacientes!A38="","",Pacientes!A38) | G38: =IF(A38="","",IF(B38<>"Sí","Sin consentimiento: excluir sus registros",IF(C38="","Falta fecha de firma",IF(C38>DATE(2026,8,3),"Firmado después del inicio del pretest (declarar)",IF(D38="Sí","Retirado: excluir desde la fecha de retiro","OK")))))
A39: =IF(Pacientes!A39="","",Pacientes!A39) | G39: =IF(A39="","",IF(B39<>"Sí","Sin consentimiento: excluir sus registros",IF(C39="","Falta fecha de firma",IF(C39>DATE(2026,8,3),"Firmado después del inicio del pretest (declarar)",IF(D39="Sí","Retirado: excluir desde la fecha de retiro","OK")))))
A40: =IF(Pacientes!A40="","",Pacientes!A40) | G40: =IF(A40="","",IF(B40<>"Sí","Sin consentimiento: excluir sus registros",IF(C40="","Falta fecha de firma",IF(C40>DATE(2026,8,3),"Firmado después del inicio del pretest (declarar)",IF(D40="Sí","Retirado: excluir desde la fecha de retiro","OK")))))
A41: =IF(Pacientes!A41="","",Pacientes!A41) | G41: =IF(A41="","",IF(B41<>"Sí","Sin consentimiento: excluir sus registros",IF(C41="","Falta fecha de firma",IF(C41>DATE(2026,8,3),"Firmado después del inicio del pretest (declarar)",IF(D41="Sí","Retirado: excluir desde la fecha de retiro","OK")))))
A42: =IF(Pacientes!A42="","",Pacientes!A42) | G42: =IF(A42="","",IF(B42<>"Sí","Sin consentimiento: excluir sus registros",IF(C42="","Falta fecha de firma",IF(C42>DATE(2026,8,3),"Firmado después del inicio del pretest (declarar)",IF(D42="Sí","Retirado: excluir desde la fecha de retiro","OK")))))
A43: =IF(Pacientes!A43="","",Pacientes!A43) | G43: =IF(A43="","",IF(B43<>"Sí","Sin consentimiento: excluir sus registros",IF(C43="","Falta fecha de firma",IF(C43>DATE(2026,8,3),"Firmado después del inicio del pretest (declarar)",IF(D43="Sí","Retirado: excluir desde la fecha de retiro","OK")))))
... A46: =IF(Pacientes!A46="","",Pacientes!A46) | G46: =IF(A46="","",IF(B46<>"Sí","Sin consentimiento: excluir sus registros",IF(C46="","Falta fecha de firma",IF(C46>DATE(2026,8,3),"Firmado después del inicio del pretest (declarar)",IF(D46="Sí","Retirado: excluir desde la fecha de retiro","OK")))))

Sheet Verificacion_VI
A1: Módulo (dimensión VI) | B1: Funcionalidad verificada | C1: Fecha de verificación | D1: Resultado | E1: Evidencia (captura, registro) | F1: Responsable
A2: Registro de pacientes | B2: Alta de un paciente nuevo con validación de campos obligatorios | C2: 46266 | D2: Implementado | E2: SIMULADO | F2: SIMULADO
A3: Registro de pacientes | B3: Almacenamiento del registro con marca de tiempo de inicio y fin | C3: 46266 | D3: Implementado | E3: SIMULADO | F3: SIMULADO
A4: Agendamiento y recordatorios | B4: Creación de una cita con fecha, hora y servicio | C4: 46266 | D4: Implementado | E4: SIMULADO | F4: SIMULADO
A5: Agendamiento y recordatorios | B5: Envío automático del recordatorio al paciente | C5: 46266 | D5: Implementado | E5: SIMULADO | F5: SIMULADO
A6: Agendamiento y recordatorios | B6: Registro de cancelación o reprogramación con aviso previo | C6: 46266 | D6: Implementado | E6: SIMULADO | F6: SIMULADO
A7: Chatbot conversacional | B7: Respuesta a una consulta de cada categoría (citas, horarios, información institucional, requisitos, ubicación, seguimiento) | C7: 46266 | D7: Implementado | E7: SIMULADO | F7: SIMULADO
A8: Chatbot conversacional | B8: Derivación al personal cuando la consulta no puede resolverse | C8: 46266 | D8: Implementado | E8: SIMULADO | F8: SIMULADO
A9: Chatbot conversacional | B9: Registro de cada consulta con su categoría, resolución y derivación | C9: 46266 | D9: Implementado | E9: SIMULADO | F9: SIMULADO

Sheet TPR_PRE
A1: ID registro | B1: Fecha | C1: Código paciente | D1: Hora inicio registro | E1: Hora fin registro | F1: TPR (min) | G1: Modalidad | H1: Control de calidad
A2: Ej. | B2: 46237 | C2: PAC-00 | D2: 0.37638889 | E2: 0.38159722 | F2: =(E2-D2)*1440 | G2: Manual
A3: =IF(B3="","",ROW()-2) | B3: 46237 | C3: SIM-14 | D3: 0.46079861 | E3: 0.46563657 | F3: =IF(OR(D3="",E3=""),"",(E3-D3)*1440) | G3: Manual | H3: =IF(B3="","",IF(OR(C3="",D3="",E3=""),"Faltan datos",IF(COUNTIF(Pacientes!$A$2:$A$46,C3)=0,"Código no registrado",IF(F3<=0,"Tiempo no válido",IF(F3>60,"Revisar: más de 60 min","OK")))))
A4: =IF(B4="","",ROW()-2) | B4: 46237 | C4: SIM-19 | D4: 0.4084375 | E4: 0.41335648 | F4: =IF(OR(D4="",E4=""),"",(E4-D4)*1440) | G4: Manual | H4: =IF(B4="","",IF(OR(C4="",D4="",E4=""),"Faltan datos",IF(COUNTIF(Pacientes!$A$2:$A$46,C4)=0,"Código no registrado",IF(F4<=0,"Tiempo no válido",IF(F4>60,"Revisar: más de 60 min","OK")))))
A5: =IF(B5="","",ROW()-2) | B5: 46239 | C5: SIM-24 | D5: 0.43833333 | E5: 0.44381944 | F5: =IF(OR(D5="",E5=""),"",(E5-D5)*1440) | G5: Manual | H5: =IF(B5="","",IF(OR(C5="",D5="",E5=""),"Faltan datos",IF(COUNTIF(Pacientes!$A$2:$A$46,C5)=0,"Código no registrado",IF(F5<=0,"Tiempo no válido",IF(F5>60,"Revisar: más de 60 min","OK")))))
A6: =IF(B6="","",ROW()-2) | B6: 46239 | C6: SIM-01 | D6: 0.4699537 | E6: 0.47670139 | F6: =IF(OR(D6="",E6=""),"",(E6-D6)*1440) | G6: Manual | H6: =IF(B6="","",IF(OR(C6="",D6="",E6=""),"Faltan datos",IF(COUNTIF(Pacientes!$A$2:$A$46,C6)=0,"Código no registrado",IF(F6<=0,"Tiempo no válido",IF(F6>60,"Revisar: más de 60 min","OK")))))
A7: =IF(B7="","",ROW()-2) | B7: 46241 | C7: SIM-14 | D7: 0.36778935 | E7: 0.3730787 | F7: =IF(OR(D7="",E7=""),"",(E7-D7)*1440) | G7: Manual | H7: =IF(B7="","",IF(OR(C7="",D7="",E7=""),"Faltan datos",IF(COUNTIF(Pacientes!$A$2:$A$46,C7)=0,"Código no registrado",IF(F7<=0,"Tiempo no válido",IF(F7>60,"Revisar: más de 60 min","OK")))))
A8: =IF(B8="","",ROW()-2) | B8: 46244 | C8: SIM-30 | D8: 0.40640046 | E8: 0.41017361 | F8: =IF(OR(D8="",E8=""),"",(E8-D8)*1440) | G8: Manual | H8: =IF(B8="","",IF(OR(C8="",D8="",E8=""),"Faltan datos",IF(COUNTIF(Pacientes!$A$2:$A$46,C8)=0,"Código no registrado",IF(F8<=0,"Tiempo no válido",IF(F8>60,"Revisar: más de 60 min","OK")))))
A9: =IF(B9="","",ROW()-2) | B9: 46248 | C9: SIM-29 | D9: 0.46707176 | E9: 0.4712037 | F9: =IF(OR(D9="",E9=""),"",(E9-D9)*1440) | G9: Manual | H9: =IF(B9="","",IF(OR(C9="",D9="",E9=""),"Faltan datos",IF(COUNTIF(Pacientes!$A$2:$A$46,C9)=0,"Código no registrado",IF(F9<=0,"Tiempo no válido",IF(F9>60,"Revisar: más de 60 min","OK")))))
A10: =IF(B10="","",ROW()-2) | B10: 46248 | C10: SIM-27 | D10: 0.44471065 | E10: 0.44974537 | F10: =IF(OR(D10="",E10=""),"",(E10-D10)*1440) | G10: Manual | H10: =IF(B10="","",IF(OR(C10="",D10="",E10=""),"Faltan datos",IF(COUNTIF(Pacientes!$A$2:$A$46,C10)=0,"Código no registrado",IF(F10<=0,"Tiempo no válido",IF(F10>60,"Revisar: más de 60 min","OK")))))
A11: =IF(B11="","",ROW()-2) | B11: 46251 | C11: SIM-04 | D11: 0.39758102 | E11: 0.40461806 | F11: =IF(OR(D11="",E11=""),"",(E11-D11)*1440) | G11: Manual | H11: =IF(B11="","",IF(OR(C11="",D11="",E11=""),"Faltan datos",IF(COUNTIF(Pacientes!$A$2:$A$46,C11)=0,"Código no registrado",IF(F11<=0,"Tiempo no válido",IF(F11>60,"Revisar: más de 60 min","OK")))))
A12: =IF(B12="","",ROW()-2) | B12: 46253 | C12: SIM-21 | D12: 0.35604167 | E12: 0.36494213 | F12: =IF(OR(D12="",E12=""),"",(E12-D12)*1440) | G12: Manual | H12: =IF(B12="","",IF(OR(C12="",D12="",E12=""),"Faltan datos",IF(COUNTIF(Pacientes!$A$2:$A$46,C12)=0,"Código no registrado",IF(F12<=0,"Tiempo no válido",IF(F12>60,"Revisar: más de 60 min","OK")))))
A13: =IF(B13="","",ROW()-2) | B13: 46255 | C13: SIM-08 | D13: 0.48809028 | E13: 0.49498843 | F13: =IF(OR(D13="",E13=""),"",(E13-D13)*1440) | G13: Manual | H13: =IF(B13="","",IF(OR(C13="",D13="",E13=""),"Faltan datos",IF(COUNTIF(Pacientes!$A$2:$A$46,C13)=0,"Código no registrado",IF(F13<=0,"Tiempo no válido",IF(F13>60,"Revisar: más de 60 min","OK")))))
A14: =IF(B14="","",ROW()-2) | B14: 46255 | C14: SIM-29 | D14: 0.46903935 | E14: 0.47494213 | F14: =IF(OR(D14="",E14=""),"",(E14-D14)*1440) | G14: Manual | H14: =IF(B14="","",IF(OR(C14="",D14="",E14=""),"Faltan datos",IF(COUNTIF(Pacientes!$A$2:$A$46,C14)=0,"Código no registrado",IF(F14<=0,"Tiempo no válido",IF(F14>60,"Revisar: más de 60 min","OK")))))
... A21: =IF(B21="","",ROW()-2) | B21: 46265 | C21: SIM-23 | D21: 0.45034722 | E21: 0.45655093 | F21: =IF(OR(D21="",E21=""),"",(E21-D21)*1440) | G21: Manual | H21: =IF(B21="","",IF(OR(C21="",D21="",E21=""),"Faltan datos",IF(COUNTIF(Pacientes!$A$2:$A$46,C21)=0,"Código no registrado",IF(F21<=0,"Tiempo no válido",IF(F21>60,"Revisar: más de 60 min","OK")))))
A22: =IF(B22="","",ROW()-2) | F22: =IF(OR(D22="",E22=""),"",(E22-D22)*1440) | G22: Manual | H22: =IF(B22="","",IF(OR(C22="",D22="",E22=""),"Faltan datos",IF(COUNTIF(Pacientes!$A$2:$A$46,C22)=0,"Código no registrado",IF(F22<=0,"Tiempo no válido",IF(F22>60,"Revisar: más de 60 min","OK")))))
A23: =IF(B23="","",ROW()-2) | F23: =IF(OR(D23="",E23=""),"",(E23-D23)*1440) | G23: Manual | H23: =IF(B23="","",IF(OR(C23="",D23="",E23=""),"Faltan datos",IF(COUNTIF(Pacientes!$A$2:$A$46,C23)=0,"Código no registrado",IF(F23<=0,"Tiempo no válido",IF(F23>60,"Revisar: más de 60 min","OK")))))
A24: =IF(B24="","",ROW()-2) | F24: =IF(OR(D24="",E24=""),"",(E24-D24)*1440) | G24: Manual | H24: =IF(B24="","",IF(OR(C24="",D24="",E24=""),"Faltan datos",IF(COUNTIF(Pacientes!$A$2:$A$46,C24)=0,"Código no registrado",IF(F24<=0,"Tiempo no válido",IF(F24>60,"Revisar: más de 60 min","OK")))))
A25: =IF(B25="","",ROW()-2) | F25: =IF(OR(D25="",E25=""),"",(E25-D25)*1440) | G25: Manual | H25: =IF(B25="","",IF(OR(C25="",D25="",E25=""),"Faltan datos",IF(COUNTIF(Pacientes!$A$2:$A$46,C25)=0,"Código no registrado",IF(F25<=0,"Tiempo no válido",IF(F25>60,"Revisar: más de 60 min","OK")))))
A26: =IF(B26="","",ROW()-2) | F26: =IF(OR(D26="",E26=""),"",(E26-D26)*1440) | G26: Manual | H26: =IF(B26="","",IF(OR(C26="",D26="",E26=""),"Faltan datos",IF(COUNTIF(Pacientes!$A$2:$A$46,C26)=0,"Código no registrado",IF(F26<=0,"Tiempo no válido",IF(F26>60,"Revisar: más de 60 min","OK")))))
A27: =IF(B27="","",ROW()-2) | F27: =IF(OR(D27="",E27=""),"",(E27-D27)*1440) | G27: Manual | H27: =IF(B27="","",IF(OR(C27="",D27="",E27=""),"Faltan datos",IF(COUNTIF(Pacientes!$A$2:$A$46,C27)=0,"Código no registrado",IF(F27<=0,"Tiempo no válido",IF(F27>60,"Revisar: más de 60 min","OK")))))
A28: =IF(B28="","",ROW()-2) | F28: =IF(OR(D28="",E28=""),"",(E28-D28)*1440) | G28: Manual | H28: =IF(B28="","",IF(OR(C28="",D28="",E28=""),"Faltan datos",IF(COUNTIF(Pacientes!$A$2:$A$46,C28)=0,"Código no registrado",IF(F28<=0,"Tiempo no válido",IF(F28>60,"Revisar: más de 60 min","OK")))))
A29: =IF(B29="","",ROW()-2) | F29: =IF(OR(D29="",E29=""),"",(E29-D29)*1440) | G29: Manual | H29: =IF(B29="","",IF(OR(C29="",D29="",E29=""),"Faltan datos",IF(COUNTIF(Pacientes!$A$2:$A$46,C29)=0,"Código no registrado",IF(F29<=0,"Tiempo no válido",IF(F29>60,"Revisar: más de 60 min","OK")))))
A30: =IF(B30="","",ROW()-2) | F30: =IF(OR(D30="",E30=""),"",(E30-D30)*1440) | G30: Manual | H30: =IF(B30="","",IF(OR(C30="",D30="",E30=""),"Faltan datos",IF(COUNTIF(Pacientes!$A$2:$A$46,C30)=0,"Código no registrado",IF(F30<=0,"Tiempo no válido",IF(F30>60,"Revisar: más de 60 min","OK")))))
A31: =IF(B31="","",ROW()-2) | F31: =IF(OR(D31="",E31=""),"",(E31-D31)*1440) | G31: Manual | H31: =IF(B31="","",IF(OR(C31="",D31="",E31=""),"Faltan datos",IF(COUNTIF(Pacientes!$A$2:$A$46,C31)=0,"Código no registrado",IF(F31<=0,"Tiempo no válido",IF(F31>60,"Revisar: más de 60 min","OK")))))
A32: =IF(B32="","",ROW()-2) | F32: =IF(OR(D32="",E32=""),"",(E32-D32)*1440) | G32: Manual | H32: =IF(B32="","",IF(OR(C32="",D32="",E32=""),"Faltan datos",IF(COUNTIF(Pacientes!$A$2:$A$46,C32)=0,"Código no registrado",IF(F32<=0,"Tiempo no válido",IF(F32>60,"Revisar: más de 60 min","OK")))))
A33: =IF(B33="","",ROW()-2) | F33: =IF(OR(D33="",E33=""),"",(E33-D33)*1440) | G33: Manual | H33: =IF(B33="","",IF(OR(C33="",D33="",E33=""),"Faltan datos",IF(COUNTIF(Pacientes!$A$2:$A$46,C33)=0,"Código no registrado",IF(F33<=0,"Tiempo no válido",IF(F33>60,"Revisar: más de 60 min","OK")))))
... A202: =IF(B202="","",ROW()-2) | F202: =IF(OR(D202="",E202=""),"",(E202-D202)*1440) | G202: Manual | H202: =IF(B202="","",IF(OR(C202="",D202="",E202=""),"Faltan datos",IF(COUNTIF(Pacientes!$A$2:$A$46,C202)=0,"Código no registrado",IF(F202<=0,"Tiempo no válido",IF(F202>60,"Revisar: más de 60 min","OK")))))

Sheet TPR_POST
A1: ID registro | B1: Fecha | C1: Código paciente | D1: Hora inicio registro | E1: Hora fin registro | F1: TPR (min) | G1: Modalidad | H1: Control de calidad
A2: Ej. | B2: 46267 | C2: PAC-00 | D2: 0.37638889 | E2: 0.38159722 | F2: =(E2-D2)*1440 | G2: Sistema
A3: =IF(B3="","",ROW()-2) | B3: 46267 | C3: SIM-11 | D3: 0.37134259 | E3: 0.37451389 | F3: =IF(OR(D3="",E3=""),"",(E3-D3)*1440) | G3: Sistema | H3: =IF(B3="","",IF(OR(C3="",D3="",E3=""),"Faltan datos",IF(COUNTIF(Pacientes!$A$2:$A$46,C3)=0,"Código no registrado",IF(F3<=0,"Tiempo no válido",IF(F3>60,"Revisar: más de 60 min","OK")))))
A4: =IF(B4="","",ROW()-2) | B4: 46269 | C4: SIM-02 | D4: 0.4628125 | E4: 0.46576389 | F4: =IF(OR(D4="",E4=""),"",(E4-D4)*1440) | G4: Sistema | H4: =IF(B4="","",IF(OR(C4="",D4="",E4=""),"Faltan datos",IF(COUNTIF(Pacientes!$A$2:$A$46,C4)=0,"Código no registrado",IF(F4<=0,"Tiempo no válido",IF(F4>60,"Revisar: más de 60 min","OK")))))
A5: =IF(B5="","",ROW()-2) | B5: 46269 | C5: SIM-07 | D5: 0.44898148 | E5: 0.45086806 | F5: =IF(OR(D5="",E5=""),"",(E5-D5)*1440) | G5: Sistema | H5: =IF(B5="","",IF(OR(C5="",D5="",E5=""),"Faltan datos",IF(COUNTIF(Pacientes!$A$2:$A$46,C5)=0,"Código no registrado",IF(F5<=0,"Tiempo no válido",IF(F5>60,"Revisar: más de 60 min","OK")))))
A6: =IF(B6="","",ROW()-2) | B6: 46269 | C6: SIM-21 | D6: 0.47699074 | E6: 0.47884259 | F6: =IF(OR(D6="",E6=""),"",(E6-D6)*1440) | G6: Sistema | H6: =IF(B6="","",IF(OR(C6="",D6="",E6=""),"Faltan datos",IF(COUNTIF(Pacientes!$A$2:$A$46,C6)=0,"Código no registrado",IF(F6<=0,"Tiempo no válido",IF(F6>60,"Revisar: más de 60 min","OK")))))
A7: =IF(B7="","",ROW()-2) | B7: 46269 | C7: SIM-21 | D7: 0.44230324 | E7: 0.44469907 | F7: =IF(OR(D7="",E7=""),"",(E7-D7)*1440) | G7: Sistema | H7: =IF(B7="","",IF(OR(C7="",D7="",E7=""),"Faltan datos",IF(COUNTIF(Pacientes!$A$2:$A$46,C7)=0,"Código no registrado",IF(F7<=0,"Tiempo no válido",IF(F7>60,"Revisar: más de 60 min","OK")))))
A8: =IF(B8="","",ROW()-2) | B8: 46272 | C8: SIM-08 | D8: 0.40564815 | E8: 0.40991898 | F8: =IF(OR(D8="",E8=""),"",(E8-D8)*1440) | G8: Sistema | H8: =IF(B8="","",IF(OR(C8="",D8="",E8=""),"Faltan datos",IF(COUNTIF(Pacientes!$A$2:$A$46,C8)=0,"Código no registrado",IF(F8<=0,"Tiempo no válido",IF(F8>60,"Revisar: más de 60 min","OK")))))
A9: =IF(B9="","",ROW()-2) | B9: 46274 | C9: SIM-07 | D9: 0.40777778 | E9: 0.409375 | F9: =IF(OR(D9="",E9=""),"",(E9-D9)*1440) | G9: Sistema | H9: =IF(B9="","",IF(OR(C9="",D9="",E9=""),"Faltan datos",IF(COUNTIF(Pacientes!$A$2:$A$46,C9)=0,"Código no registrado",IF(F9<=0,"Tiempo no válido",IF(F9>60,"Revisar: más de 60 min","OK")))))
A10: =IF(B10="","",ROW()-2) | B10: 46276 | C10: SIM-21 | D10: 0.43960648 | E10: 0.44366898 | F10: =IF(OR(D10="",E10=""),"",(E10-D10)*1440) | G10: Sistema | H10: =IF(B10="","",IF(OR(C10="",D10="",E10=""),"Faltan datos",IF(COUNTIF(Pacientes!$A$2:$A$46,C10)=0,"Código no registrado",IF(F10<=0,"Tiempo no válido",IF(F10>60,"Revisar: más de 60 min","OK")))))
A11: =IF(B11="","",ROW()-2) | B11: 46276 | C11: SIM-21 | D11: 0.37277778 | E11: 0.37571759 | F11: =IF(OR(D11="",E11=""),"",(E11-D11)*1440) | G11: Sistema | H11: =IF(B11="","",IF(OR(C11="",D11="",E11=""),"Faltan datos",IF(COUNTIF(Pacientes!$A$2:$A$46,C11)=0,"Código no registrado",IF(F11<=0,"Tiempo no válido",IF(F11>60,"Revisar: más de 60 min","OK")))))
A12: =IF(B12="","",ROW()-2) | B12: 46279 | C12: SIM-09 | D12: 0.4647338 | E12: 0.46680556 | F12: =IF(OR(D12="",E12=""),"",(E12-D12)*1440) | G12: Sistema | H12: =IF(B12="","",IF(OR(C12="",D12="",E12=""),"Faltan datos",IF(COUNTIF(Pacientes!$A$2:$A$46,C12)=0,"Código no registrado",IF(F12<=0,"Tiempo no válido",IF(F12>60,"Revisar: más de 60 min","OK")))))
A13: =IF(B13="","",ROW()-2) | B13: 46281 | C13: SIM-14 | D13: 0.36043981 | E13: 0.36384259 | F13: =IF(OR(D13="",E13=""),"",(E13-D13)*1440) | G13: Sistema | H13: =IF(B13="","",IF(OR(C13="",D13="",E13=""),"Faltan datos",IF(COUNTIF(Pacientes!$A$2:$A$46,C13)=0,"Código no registrado",IF(F13<=0,"Tiempo no válido",IF(F13>60,"Revisar: más de 60 min","OK")))))
A14: =IF(B14="","",ROW()-2) | B14: 46281 | C14: SIM-21 | D14: 0.35859954 | E14: 0.36380787 | F14: =IF(OR(D14="",E14=""),"",(E14-D14)*1440) | G14: Sistema | H14: =IF(B14="","",IF(OR(C14="",D14="",E14=""),"Faltan datos",IF(COUNTIF(Pacientes!$A$2:$A$46,C14)=0,"Código no registrado",IF(F14<=0,"Tiempo no válido",IF(F14>60,"Revisar: más de 60 min","OK")))))
... A23: =IF(B23="","",ROW()-2) | B23: 46295 | C23: SIM-07 | D23: 0.46271991 | E23: 0.46572917 | F23: =IF(OR(D23="",E23=""),"",(E23-D23)*1440) | G23: Sistema | H23: =IF(B23="","",IF(OR(C23="",D23="",E23=""),"Faltan datos",IF(COUNTIF(Pacientes!$A$2:$A$46,C23)=0,"Código no registrado",IF(F23<=0,"Tiempo no válido",IF(F23>60,"Revisar: más de 60 min","OK")))))
A24: =IF(B24="","",ROW()-2) | F24: =IF(OR(D24="",E24=""),"",(E24-D24)*1440) | G24: Sistema | H24: =IF(B24="","",IF(OR(C24="",D24="",E24=""),"Faltan datos",IF(COUNTIF(Pacientes!$A$2:$A$46,C24)=0,"Código no registrado",IF(F24<=0,"Tiempo no válido",IF(F24>60,"Revisar: más de 60 min","OK")))))
A25: =IF(B25="","",ROW()-2) | F25: =IF(OR(D25="",E25=""),"",(E25-D25)*1440) | G25: Sistema | H25: =IF(B25="","",IF(OR(C25="",D25="",E25=""),"Faltan datos",IF(COUNTIF(Pacientes!$A$2:$A$46,C25)=0,"Código no registrado",IF(F25<=0,"Tiempo no válido",IF(F25>60,"Revisar: más de 60 min","OK")))))
A26: =IF(B26="","",ROW()-2) | F26: =IF(OR(D26="",E26=""),"",(E26-D26)*1440) | G26: Sistema | H26: =IF(B26="","",IF(OR(C26="",D26="",E26=""),"Faltan datos",IF(COUNTIF(Pacientes!$A$2:$A$46,C26)=0,"Código no registrado",IF(F26<=0,"Tiempo no válido",IF(F26>60,"Revisar: más de 60 min","OK")))))
A27: =IF(B27="","",ROW()-2) | F27: =IF(OR(D27="",E27=""),"",(E27-D27)*1440) | G27: Sistema | H27: =IF(B27="","",IF(OR(C27="",D27="",E27=""),"Faltan datos",IF(COUNTIF(Pacientes!$A$2:$A$46,C27)=0,"Código no registrado",IF(F27<=0,"Tiempo no válido",IF(F27>60,"Revisar: más de 60 min","OK")))))
A28: =IF(B28="","",ROW()-2) | F28: =IF(OR(D28="",E28=""),"",(E28-D28)*1440) | G28: Sistema | H28: =IF(B28="","",IF(OR(C28="",D28="",E28=""),"Faltan datos",IF(COUNTIF(Pacientes!$A$2:$A$46,C28)=0,"Código no registrado",IF(F28<=0,"Tiempo no válido",IF(F28>60,"Revisar: más de 60 min","OK")))))
A29: =IF(B29="","",ROW()-2) | F29: =IF(OR(D29="",E29=""),"",(E29-D29)*1440) | G29: Sistema | H29: =IF(B29="","",IF(OR(C29="",D29="",E29=""),"Faltan datos",IF(COUNTIF(Pacientes!$A$2:$A$46,C29)=0,"Código no registrado",IF(F29<=0,"Tiempo no válido",IF(F29>60,"Revisar: más de 60 min","OK")))))
A30: =IF(B30="","",ROW()-2) | F30: =IF(OR(D30="",E30=""),"",(E30-D30)*1440) | G30: Sistema | H30: =IF(B30="","",IF(OR(C30="",D30="",E30=""),"Faltan datos",IF(COUNTIF(Pacientes!$A$2:$A$46,C30)=0,"Código no registrado",IF(F30<=0,"Tiempo no válido",IF(F30>60,"Revisar: más de 60 min","OK")))))
A31: =IF(B31="","",ROW()-2) | F31: =IF(OR(D31="",E31=""),"",(E31-D31)*1440) | G31: Sistema | H31: =IF(B31="","",IF(OR(C31="",D31="",E31=""),"Faltan datos",IF(COUNTIF(Pacientes!$A$2:$A$46,C31)=0,"Código no registrado",IF(F31<=0,"Tiempo no válido",IF(F31>60,"Revisar: más de 60 min","OK")))))
A32: =IF(B32="","",ROW()-2) | F32: =IF(OR(D32="",E32=""),"",(E32-D32)*1440) | G32: Sistema | H32: =IF(B32="","",IF(OR(C32="",D32="",E32=""),"Faltan datos",IF(COUNTIF(Pacientes!$A$2:$A$46,C32)=0,"Código no registrado",IF(F32<=0,"Tiempo no válido",IF(F32>60,"Revisar: más de 60 min","OK")))))
A33: =IF(B33="","",ROW()-2) | F33: =IF(OR(D33="",E33=""),"",(E33-D33)*1440) | G33: Sistema | H33: =IF(B33="","",IF(OR(C33="",D33="",E33=""),"Faltan datos",IF(COUNTIF(Pacientes!$A$2:$A$46,C33)=0,"Código no registrado",IF(F33<=0,"Tiempo no válido",IF(F33>60,"Revisar: más de 60 min","OK")))))
A34: =IF(B34="","",ROW()-2) | F34: =IF(OR(D34="",E34=""),"",(E34-D34)*1440) | G34: Sistema | H34: =IF(B34="","",IF(OR(C34="",D34="",E34=""),"Faltan datos",IF(COUNTIF(Pacientes!$A$2:$A$46,C34)=0,"Código no registrado",IF(F34<=0,"Tiempo no válido",IF(F34>60,"Revisar: más de 60 min","OK")))))
A35: =IF(B35="","",ROW()-2) | F35: =IF(OR(D35="",E35=""),"",(E35-D35)*1440) | G35: Sistema | H35: =IF(B35="","",IF(OR(C35="",D35="",E35=""),"Faltan datos",IF(COUNTIF(Pacientes!$A$2:$A$46,C35)=0,"Código no registrado",IF(F35<=0,"Tiempo no válido",IF(F35>60,"Revisar: más de 60 min","OK")))))
... A202: =IF(B202="","",ROW()-2) | F202: =IF(OR(D202="",E202=""),"",(E202-D202)*1440) | G202: Sistema | H202: =IF(B202="","",IF(OR(C202="",D202="",E202=""),"Faltan datos",IF(COUNTIF(Pacientes!$A$2:$A$46,C202)=0,"Código no registrado",IF(F202<=0,"Tiempo no válido",IF(F202>60,"Revisar: más de 60 min","OK")))))

Sheet Ausentismo_PRE
A1: ID cita | B1: Fecha | C1: Código paciente | D1: Cita programada | E1: Estado | F1: Motivo (si no asistió) | G1: Recordatorio enviado | H1: Control de calidad
A2: Ej. | B2: 46237 | C2: PAC-00 | D2: Sí | E2: No asistió | F2: Sin aviso | G2: No
A3: =IF(B3="","",ROW()-2) | B3: 46237 | C3: SIM-24 | D3: Sí | E3: Asistió | G3: No | H3: =IF(B3="","",IF(OR(C3="",E3=""),"Faltan datos",IF(COUNTIF(Pacientes!$A$2:$A$46,C3)=0,"Código no registrado","OK")))
A4: =IF(B4="","",ROW()-2) | B4: 46237 | C4: SIM-07 | D4: Sí | E4: Cancelada | F4: Aviso previo | G4: No | H4: =IF(B4="","",IF(OR(C4="",E4=""),"Faltan datos",IF(COUNTIF(Pacientes!$A$2:$A$46,C4)=0,"Código no registrado","OK")))
A5: =IF(B5="","",ROW()-2) | B5: 46237 | C5: SIM-27 | D5: Sí | E5: Asistió | G5: No | H5: =IF(B5="","",IF(OR(C5="",E5=""),"Faltan datos",IF(COUNTIF(Pacientes!$A$2:$A$46,C5)=0,"Código no registrado","OK")))
A6: =IF(B6="","",ROW()-2) | B6: 46237 | C6: SIM-21 | D6: Sí | E6: Asistió | G6: No | H6: =IF(B6="","",IF(OR(C6="",E6=""),"Faltan datos",IF(COUNTIF(Pacientes!$A$2:$A$46,C6)=0,"Código no registrado","OK")))
A7: =IF(B7="","",ROW()-2) | B7: 46237 | C7: SIM-01 | D7: Sí | E7: Asistió | G7: No | H7: =IF(B7="","",IF(OR(C7="",E7=""),"Faltan datos",IF(COUNTIF(Pacientes!$A$2:$A$46,C7)=0,"Código no registrado","OK")))
A8: =IF(B8="","",ROW()-2) | B8: 46237 | C8: SIM-24 | D8: Sí | E8: Asistió | G8: No | H8: =IF(B8="","",IF(OR(C8="",E8=""),"Faltan datos",IF(COUNTIF(Pacientes!$A$2:$A$46,C8)=0,"Código no registrado","OK")))
A9: =IF(B9="","",ROW()-2) | B9: 46237 | C9: SIM-06 | D9: Sí | E9: Asistió | G9: No | H9: =IF(B9="","",IF(OR(C9="",E9=""),"Faltan datos",IF(COUNTIF(Pacientes!$A$2:$A$46,C9)=0,"Código no registrado","OK")))
A10: =IF(B10="","",ROW()-2) | B10: 46237 | C10: SIM-27 | D10: Sí | E10: Asistió | G10: No | H10: =IF(B10="","",IF(OR(C10="",E10=""),"Faltan datos",IF(COUNTIF(Pacientes!$A$2:$A$46,C10)=0,"Código no registrado","OK")))
A11: =IF(B11="","",ROW()-2) | B11: 46237 | C11: SIM-13 | D11: Sí | E11: Asistió | G11: No | H11: =IF(B11="","",IF(OR(C11="",E11=""),"Faltan datos",IF(COUNTIF(Pacientes!$A$2:$A$46,C11)=0,"Código no registrado","OK")))
A12: =IF(B12="","",ROW()-2) | B12: 46237 | C12: SIM-10 | D12: Sí | E12: Asistió | G12: Sí | H12: =IF(B12="","",IF(OR(C12="",E12=""),"Faltan datos",IF(COUNTIF(Pacientes!$A$2:$A$46,C12)=0,"Código no registrado","OK")))
A13: =IF(B13="","",ROW()-2) | B13: 46237 | C13: SIM-27 | D13: Sí | E13: Asistió | G13: No | H13: =IF(B13="","",IF(OR(C13="",E13=""),"Faltan datos",IF(COUNTIF(Pacientes!$A$2:$A$46,C13)=0,"Código no registrado","OK")))
A14: =IF(B14="","",ROW()-2) | B14: 46239 | C14: SIM-18 | D14: Sí | E14: Asistió | G14: No | H14: =IF(B14="","",IF(OR(C14="",E14=""),"Faltan datos",IF(COUNTIF(Pacientes!$A$2:$A$46,C14)=0,"Código no registrado","OK")))
A15: =IF(B15="","",ROW()-2) | B15: 46239 | C15: SIM-23 | D15: Sí | E15: Asistió | G15: No | H15: =IF(B15="","",IF(OR(C15="",E15=""),"Faltan datos",IF(COUNTIF(Pacientes!$A$2:$A$46,C15)=0,"Código no registrado","OK")))
A16: =IF(B16="","",ROW()-2) | B16: 46239 | C16: SIM-21 | D16: Sí | E16: Asistió | G16: No | H16: =IF(B16="","",IF(OR(C16="",E16=""),"Faltan datos",IF(COUNTIF(Pacientes!$A$2:$A$46,C16)=0,"Código no registrado","OK")))
A17: =IF(B17="","",ROW()-2) | B17: 46239 | C17: SIM-26 | D17: Sí | E17: Cancelada | F17: Aviso previo | G17: No | H17: =IF(B17="","",IF(OR(C17="",E17=""),"Faltan datos",IF(COUNTIF(Pacientes!$A$2:$A$46,C17)=0,"Código no registrado","OK")))
A18: =IF(B18="","",ROW()-2) | B18: 46239 | C18: SIM-30 | D18: Sí | E18: Asistió | G18: Sí | H18: =IF(B18="","",IF(OR(C18="",E18=""),"Faltan datos",IF(COUNTIF(Pacientes!$A$2:$A$46,C18)=0,"Código no registrado","OK")))
A19: =IF(B19="","",ROW()-2) | B19: 46239 | C19: SIM-10 | D19: Sí | E19: Asistió | G19: No | H19: =IF(B19="","",IF(OR(C19="",E19=""),"Faltan datos",IF(COUNTIF(Pacientes!$A$2:$A$46,C19)=0,"Código no registrado","OK")))
A20: =IF(B20="","",ROW()-2) | B20: 46239 | C20: SIM-03 | D20: Sí | E20: Asistió | G20: No | H20: =IF(B20="","",IF(OR(C20="",E20=""),"Faltan datos",IF(COUNTIF(Pacientes!$A$2:$A$46,C20)=0,"Código no registrado","OK")))
A21: =IF(B21="","",ROW()-2) | B21: 46239 | C21: SIM-10 | D21: Sí | E21: Asistió | G21: No | H21: =IF(B21="","",IF(OR(C21="",E21=""),"Faltan datos",IF(COUNTIF(Pacientes!$A$2:$A$46,C21)=0,"Código no registrado","OK")))
A22: =IF(B22="","",ROW()-2) | B22: 46239 | C22: SIM-04 | D22: Sí | E22: No asistió | F22: Sin aviso | G22: No | H22: =IF(B22="","",IF(OR(C22="",E22=""),"Faltan datos",IF(COUNTIF(Pacientes!$A$2:$A$46,C22)=0,"Código no registrado","OK")))
A23: =IF(B23="","",ROW()-2) | B23: 46239 | C23: SIM-02 | D23: Sí | E23: Asistió | G23: No | H23: =IF(B23="","",IF(OR(C23="",E23=""),"Faltan datos",IF(COUNTIF(Pacientes!$A$2:$A$46,C23)=0,"Código no registrado","OK")))
A24: =IF(B24="","",ROW()-2) | B24: 46241 | C24: SIM-02 | D24: Sí | E24: Asistió | G24: No | H24: =IF(B24="","",IF(OR(C24="",E24=""),"Faltan datos",IF(COUNTIF(Pacientes!$A$2:$A$46,C24)=0,"Código no registrado","OK")))
A25: =IF(B25="","",ROW()-2) | B25: 46241 | C25: SIM-30 | D25: Sí | E25: Asistió | G25: No | H25: =IF(B25="","",IF(OR(C25="",E25=""),"Faltan datos",IF(COUNTIF(Pacientes!$A$2:$A$46,C25)=0,"Código no registrado","OK")))
A26: =IF(B26="","",ROW()-2) | B26: 46241 | C26: SIM-25 | D26: Sí | E26: No asistió | F26: Sin aviso | G26: No | H26: =IF(B26="","",IF(OR(C26="",E26=""),"Faltan datos",IF(COUNTIF(Pacientes!$A$2:$A$46,C26)=0,"Código no registrado","OK")))
A27: =IF(B27="","",ROW()-2) | B27: 46241 | C27: SIM-07 | D27: Sí | E27: Asistió | G27: No | H27: =IF(B27="","",IF(OR(C27="",E27=""),"Faltan datos",IF(COUNTIF(Pacientes!$A$2:$A$46,C27)=0,"Código no registrado","OK")))
A28: =IF(B28="","",ROW()-2) | B28: 46241 | C28: SIM-03 | D28: Sí | E28: Asistió | G28: No | H28: =IF(B28="","",IF(OR(C28="",E28=""),"Faltan datos",IF(COUNTIF(Pacientes!$A$2:$A$46,C28)=0,"Código no registrado","OK")))
A29: =IF(B29="","",ROW()-2) | B29: 46241 | C29: SIM-02 | D29: Sí | E29: Reprogramada | F29: Aviso previo | G29: No | H29: =IF(B29="","",IF(OR(C29="",E29=""),"Faltan datos",IF(COUNTIF(Pacientes!$A$2:$A$46,C29)=0,"Código no registrado","OK")))
A30: =IF(B30="","",ROW()-2) | B30: 46241 | C30: SIM-17 | D30: Sí | E30: Asistió | G30: Sí | H30: =IF(B30="","",IF(OR(C30="",E30=""),"Faltan datos",IF(COUNTIF(Pacientes!$A$2:$A$46,C30)=0,"Código no registrado","OK")))
A31: =IF(B31="","",ROW()-2) | B31: 46241 | C31: SIM-18 | D31: Sí | E31: Asistió | G31: No | H31: =IF(B31="","",IF(OR(C31="",E31=""),"Faltan datos",IF(COUNTIF(Pacientes!$A$2:$A$46,C31)=0,"Código no registrado","OK")))
A32: =IF(B32="","",ROW()-2) | B32: 46241 | C32: SIM-13 | D32: Sí | E32: Asistió | G32: No | H32: =IF(B32="","",IF(OR(C32="",E32=""),"Faltan datos",IF(COUNTIF(Pacientes!$A$2:$A$46,C32)=0,"Código no registrado","OK")))
A33: =IF(B33="","",ROW()-2) | B33: 46241 | C33: SIM-23 | D33: Sí | E33: Asistió | G33: No | H33: =IF(B33="","",IF(OR(C33="",E33=""),"Faltan datos",IF(COUNTIF(Pacientes!$A$2:$A$46,C33)=0,"Código no registrado","OK")))
A34: =IF(B34="","",ROW()-2) | B34: 46241 | C34: SIM-30 | D34: Sí | E34: Cancelada | F34: Aviso previo | G34: No | H34: =IF(B34="","",IF(OR(C34="",E34=""),"Faltan datos",IF(COUNTIF(Pacientes!$A$2:$A$46,C34)=0,"Código no registrado","OK")))
A35: =IF(B35="","",ROW()-2) | B35: 46241 | C35: SIM-27 | D35: Sí | E35: Reprogramada | F35: Aviso previo | G35: No | H35: =IF(B35="","",IF(OR(C35="",E35=""),"Faltan datos",IF(COUNTIF(Pacientes!$A$2:$A$46,C35)=0,"Código no registrado","OK")))
A36: =IF(B36="","",ROW()-2) | B36: 46244 | C36: SIM-24 | D36: Sí | E36: Asistió | G36: No | H36: =IF(B36="","",IF(OR(C36="",E36=""),"Faltan datos",IF(COUNTIF(Pacientes!$A$2:$A$46,C36)=0,"Código no registrado","OK")))
A37: =IF(B37="","",ROW()-2) | B37: 46244 | C37: SIM-08 | D37: Sí | E37: Cancelada | F37: Aviso previo | G37: No | H37: =IF(B37="","",IF(OR(C37="",E37=""),"Faltan datos",IF(COUNTIF(Pacientes!$A$2:$A$46,C37)=0,"Código no registrado","OK")))
A38: =IF(B38="","",ROW()-2) | B38: 46244 | C38: SIM-13 | D38: Sí | E38: Asistió | G38: No | H38: =IF(B38="","",IF(OR(C38="",E38=""),"Faltan datos",IF(COUNTIF(Pacientes!$A$2:$A$46,C38)=0,"Código no registrado","OK")))
A39: =IF(B39="","",ROW()-2) | B39: 46244 | C39: SIM-07 | D39: Sí | E39: Asistió | G39: No | H39: =IF(B39="","",IF(OR(C39="",E39=""),"Faltan datos",IF(COUNTIF(Pacientes!$A$2:$A$46,C39)=0,"Código no registrado","OK")))
A40: =IF(B40="","",ROW()-2) | B40: 46244 | C40: SIM-16 | D40: Sí | E40: No asistió | F40: Sin aviso | G40: No | H40: =IF(B40="","",IF(OR(C40="",E40=""),"Faltan datos",IF(COUNTIF(Pacientes!$A$2:$A$46,C40)=0,"Código no registrado","OK")))
...

Sheet Ausentismo_POST
A1: ID cita | B1: Fecha | C1: Código paciente | D1: Cita programada | E1: Estado | F1: Motivo (si no asistió) | G1: Recordatorio enviado | H1: Control de calidad
A2: Ej. | B2: 46267 | C2: PAC-00 | D2: Sí | E2: No asistió | F2: Sin aviso | G2: No
A3: =IF(B3="","",ROW()-2) | B3: 46267 | C3: SIM-23 | D3: Sí | E3: Asistió | G3: Sí | H3: =IF(B3="","",IF(OR(C3="",E3=""),"Faltan datos",IF(COUNTIF(Pacientes!$A$2:$A$46,C3)=0,"Código no registrado","OK")))
A4: =IF(B4="","",ROW()-2) | B4: 46267 | C4: SIM-30 | D4: Sí | E4: Asistió | G4: Sí | H4: =IF(B4="","",IF(OR(C4="",E4=""),"Faltan datos",IF(COUNTIF(Pacientes!$A$2:$A$46,C4)=0,"Código no registrado","OK")))
A5: =IF(B5="","",ROW()-2) | B5: 46267 | C5: SIM-16 | D5: Sí | E5: Cancelada | F5: Aviso previo | G5: Sí | H5: =IF(B5="","",IF(OR(C5="",E5=""),"Faltan datos",IF(COUNTIF(Pacientes!$A$2:$A$46,C5)=0,"Código no registrado","OK")))
A6: =IF(B6="","",ROW()-2) | B6: 46267 | C6: SIM-30 | D6: Sí | E6: Asistió | G6: Sí | H6: =IF(B6="","",IF(OR(C6="",E6=""),"Faltan datos",IF(COUNTIF(Pacientes!$A$2:$A$46,C6)=0,"Código no registrado","OK")))
A7: =IF(B7="","",ROW()-2) | B7: 46267 | C7: SIM-26 | D7: Sí | E7: No asistió | F7: Sin aviso | G7: Sí | H7: =IF(B7="","",IF(OR(C7="",E7=""),"Faltan datos",IF(COUNTIF(Pacientes!$A$2:$A$46,C7)=0,"Código no registrado","OK")))
A8: =IF(B8="","",ROW()-2) | B8: 46267 | C8: SIM-27 | D8: Sí | E8: Asistió | G8: Sí | H8: =IF(B8="","",IF(OR(C8="",E8=""),"Faltan datos",IF(COUNTIF(Pacientes!$A$2:$A$46,C8)=0,"Código no registrado","OK")))
A9: =IF(B9="","",ROW()-2) | B9: 46267 | C9: SIM-16 | D9: Sí | E9: Cancelada | F9: Aviso previo | G9: Sí | H9: =IF(B9="","",IF(OR(C9="",E9=""),"Faltan datos",IF(COUNTIF(Pacientes!$A$2:$A$46,C9)=0,"Código no registrado","OK")))
A10: =IF(B10="","",ROW()-2) | B10: 46267 | C10: SIM-15 | D10: Sí | E10: Asistió | G10: Sí | H10: =IF(B10="","",IF(OR(C10="",E10=""),"Faltan datos",IF(COUNTIF(Pacientes!$A$2:$A$46,C10)=0,"Código no registrado","OK")))
A11: =IF(B11="","",ROW()-2) | B11: 46267 | C11: SIM-23 | D11: Sí | E11: Asistió | G11: No | H11: =IF(B11="","",IF(OR(C11="",E11=""),"Faltan datos",IF(COUNTIF(Pacientes!$A$2:$A$46,C11)=0,"Código no registrado","OK")))
A12: =IF(B12="","",ROW()-2) | B12: 46267 | C12: SIM-02 | D12: Sí | E12: Asistió | G12: Sí | H12: =IF(B12="","",IF(OR(C12="",E12=""),"Faltan datos",IF(COUNTIF(Pacientes!$A$2:$A$46,C12)=0,"Código no registrado","OK")))
A13: =IF(B13="","",ROW()-2) | B13: 46267 | C13: SIM-21 | D13: Sí | E13: Asistió | G13: No | H13: =IF(B13="","",IF(OR(C13="",E13=""),"Faltan datos",IF(COUNTIF(Pacientes!$A$2:$A$46,C13)=0,"Código no registrado","OK")))
A14: =IF(B14="","",ROW()-2) | B14: 46267 | C14: SIM-16 | D14: Sí | E14: Asistió | G14: Sí | H14: =IF(B14="","",IF(OR(C14="",E14=""),"Faltan datos",IF(COUNTIF(Pacientes!$A$2:$A$46,C14)=0,"Código no registrado","OK")))
A15: =IF(B15="","",ROW()-2) | B15: 46269 | C15: SIM-09 | D15: Sí | E15: Asistió | G15: Sí | H15: =IF(B15="","",IF(OR(C15="",E15=""),"Faltan datos",IF(COUNTIF(Pacientes!$A$2:$A$46,C15)=0,"Código no registrado","OK")))
A16: =IF(B16="","",ROW()-2) | B16: 46269 | C16: SIM-16 | D16: Sí | E16: Asistió | G16: Sí | H16: =IF(B16="","",IF(OR(C16="",E16=""),"Faltan datos",IF(COUNTIF(Pacientes!$A$2:$A$46,C16)=0,"Código no registrado","OK")))
A17: =IF(B17="","",ROW()-2) | B17: 46269 | C17: SIM-16 | D17: Sí | E17: Asistió | G17: Sí | H17: =IF(B17="","",IF(OR(C17="",E17=""),"Faltan datos",IF(COUNTIF(Pacientes!$A$2:$A$46,C17)=0,"Código no registrado","OK")))
A18: =IF(B18="","",ROW()-2) | B18: 46269 | C18: SIM-01 | D18: Sí | E18: Asistió | G18: Sí | H18: =IF(B18="","",IF(OR(C18="",E18=""),"Faltan datos",IF(COUNTIF(Pacientes!$A$2:$A$46,C18)=0,"Código no registrado","OK")))
A19: =IF(B19="","",ROW()-2) | B19: 46269 | C19: SIM-27 | D19: Sí | E19: Asistió | G19: Sí | H19: =IF(B19="","",IF(OR(C19="",E19=""),"Faltan datos",IF(COUNTIF(Pacientes!$A$2:$A$46,C19)=0,"Código no registrado","OK")))
A20: =IF(B20="","",ROW()-2) | B20: 46269 | C20: SIM-04 | D20: Sí | E20: Asistió | G20: Sí | H20: =IF(B20="","",IF(OR(C20="",E20=""),"Faltan datos",IF(COUNTIF(Pacientes!$A$2:$A$46,C20)=0,"Código no registrado","OK")))
A21: =IF(B21="","",ROW()-2) | B21: 46269 | C21: SIM-28 | D21: Sí | E21: Asistió | G21: No | H21: =IF(B21="","",IF(OR(C21="",E21=""),"Faltan datos",IF(COUNTIF(Pacientes!$A$2:$A$46,C21)=0,"Código no registrado","OK")))
... A23: =IF(B23="","",ROW()-2) | B23: 46269 | C23: SIM-07 | D23: Sí | E23: Asistió | G23: Sí | H23: =IF(B23="","",IF(OR(C23="",E23=""),"Faltan datos",IF(COUNTIF(Pacientes!$A$2:$A$46,C23)=0,"Código no registrado","OK")))
A24: =IF(B24="","",ROW()-2) | B24: 46269 | C24: SIM-24 | D24: Sí | E24: Cancelada | F24: Aviso previo | G24: Sí | H24: =IF(B24="","",IF(OR(C24="",E24=""),"Faltan datos",IF(COUNTIF(Pacientes!$A$2:$A$46,C24)=0,"Código no registrado","OK")))
A25: =IF(B25="","",ROW()-2) | B25: 46272 | C25: SIM-16 | D25: Sí | E25: No asistió | F25: Sin aviso | G25: Sí | H25: =IF(B25="","",IF(OR(C25="",E25=""),"Faltan datos",IF(COUNTIF(Pacientes!$A$2:$A$46,C25)=0,"Código no registrado","OK")))
A26: =IF(B26="","",ROW()-2) | B26: 46272 | C26: SIM-02 | D26: Sí | E26: Asistió | G26: Sí | H26: =IF(B26="","",IF(OR(C26="",E26=""),"Faltan datos",IF(COUNTIF(Pacientes!$A$2:$A$46,C26)=0,"Código no registrado","OK")))
A27: =IF(B27="","",ROW()-2) | B27: 46272 | C27: SIM-25 | D27: Sí | E27: Cancelada | F27: Aviso previo | G27: Sí | H27: =IF(B27="","",IF(OR(C27="",E27=""),"Faltan datos",IF(COUNTIF(Pacientes!$A$2:$A$46,C27)=0,"Código no registrado","OK")))
A28: =IF(B28="","",ROW()-2) | B28: 46272 | C28: SIM-07 | D28: Sí | E28: Asistió | G28: Sí | H28: =IF(B28="","",IF(OR(C28="",E28=""),"Faltan datos",IF(COUNTIF(Pacientes!$A$2:$A$46,C28)=0,"Código no registrado","OK")))
A29: =IF(B29="","",ROW()-2) | B29: 46272 | C29: SIM-20 | D29: Sí | E29: Asistió | G29: Sí | H29: =IF(B29="","",IF(OR(C29="",E29=""),"Faltan datos",IF(COUNTIF(Pacientes!$A$2:$A$46,C29)=0,"Código no registrado","OK")))
A30: =IF(B30="","",ROW()-2) | B30: 46272 | C30: SIM-25 | D30: Sí | E30: Asistió | G30: Sí | H30: =IF(B30="","",IF(OR(C30="",E30=""),"Faltan datos",IF(COUNTIF(Pacientes!$A$2:$A$46,C30)=0,"Código no registrado","OK")))
A31: =IF(B31="","",ROW()-2) | B31: 46272 | C31: SIM-26 | D31: Sí | E31: Asistió | G31: Sí | H31: =IF(B31="","",IF(OR(C31="",E31=""),"Faltan datos",IF(COUNTIF(Pacientes!$A$2:$A$46,C31)=0,"Código no registrado","OK")))
A32: =IF(B32="","",ROW()-2) | B32: 46272 | C32: SIM-22 | D32: Sí | E32: Asistió | G32: Sí | H32: =IF(B32="","",IF(OR(C32="",E32=""),"Faltan datos",IF(COUNTIF(Pacientes!$A$2:$A$46,C32)=0,"Código no registrado","OK")))
A33: =IF(B33="","",ROW()-2) | B33: 46272 | C33: SIM-02 | D33: Sí | E33: No asistió | F33: Sin aviso | G33: Sí | H33: =IF(B33="","",IF(OR(C33="",E33=""),"Faltan datos",IF(COUNTIF(Pacientes!$A$2:$A$46,C33)=0,"Código no registrado","OK")))
A34: =IF(B34="","",ROW()-2) | B34: 46272 | C34: SIM-19 | D34: Sí | E34: Asistió | G34: Sí | H34: =IF(B34="","",IF(OR(C34="",E34=""),"Faltan datos",IF(COUNTIF(Pacientes!$A$2:$A$46,C34)=0,"Código no registrado","OK")))
A35: =IF(B35="","",ROW()-2) | B35: 46272 | C35: SIM-22 | D35: Sí | E35: Asistió | G35: Sí | H35: =IF(B35="","",IF(OR(C35="",E35=""),"Faltan datos",IF(COUNTIF(Pacientes!$A$2:$A$46,C35)=0,"Código no registrado","OK")))
A36: =IF(B36="","",ROW()-2) | B36: 46274 | C36: SIM-29 | D36: Sí | E36: Asistió | G36: Sí | H36: =IF(B36="","",IF(OR(C36="",E36=""),"Faltan datos",IF(COUNTIF(Pacientes!$A$2:$A$46,C36)=0,"Código no registrado","OK")))
A37: =IF(B37="","",ROW()-2) | B37: 46274 | C37: SIM-27 | D37: Sí | E37: Asistió | G37: Sí | H37: =IF(B37="","",IF(OR(C37="",E37=""),"Faltan datos",IF(COUNTIF(Pacientes!$A$2:$A$46,C37)=0,"Código no registrado","OK")))
A38: =IF(B38="","",ROW()-2) | B38: 46274 | C38: SIM-27 | D38: Sí | E38: Reprogramada | F38: Aviso previo | G38: Sí | H38: =IF(B38="","",IF(OR(C38="",E38=""),"Faltan datos",IF(COUNTIF(Pacientes!$A$2:$A$46,C38)=0,"Código no registrado","OK")))
A39: =IF(B39="","",ROW()-2) | B39: 46274 | C39: SIM-01 | D39: Sí | E39: Asistió | G39: Sí | H39: =IF(B39="","",IF(OR(C39="",E39=""),"Faltan datos",IF(COUNTIF(Pacientes!$A$2:$A$46,C39)=0,"Código no registrado","OK")))
A40: =IF(B40="","",ROW()-2) | B40: 46274 | C40: SIM-22 | D40: Sí | E40: Asistió | G40: Sí | H40: =IF(B40="","",IF(OR(C40="",E40=""),"Faltan datos",IF(COUNTIF(Pacientes!$A$2:$A$46,C40)=0,"Código no registrado","OK")))
A41: =IF(B41="","",ROW()-2) | B41: 46274 | C41: SIM-10 | D41: Sí | E41: Asistió | G41: Sí | H41: =IF(B41="","",IF(OR(C41="",E41=""),"Faltan datos",IF(COUNTIF(Pacientes!$A$2:$A$46,C41)=0,"Código no registrado","OK")))
...

Sheet Consultas_PRE
A1: ID consulta | B1: Fecha | C1: Código paciente | D1: Categoría | E1: Canal | F1: Resuelta en el primer contacto | G1: Derivada a otra persona o área | H1: Tiempo de respuesta (min) | I1: Control de calidad
A2: Ej. | B2: 46237 | C2: PAC-00 | D2: Horarios | E2: Presencial | F2: Sí | G2: No | H2: 3
A3: =IF(B3="","",ROW()-2) | B3: 46237 | C3: SIM-02 | D3: Citas | E3: Presencial | F3: No | G3: Sí | H3: 6.2 | I3: =IF(B3="","",IF(OR(D3="",F3="",G3=""),"Faltan datos",IF(AND(C3<>"",COUNTIF(Pacientes!$A$2:$A$46,C3)=0),"Código no registrado",IF(AND(F3="Sí",G3="Sí"),"Contradicción: resuelta y derivada","OK"))))
A4: =IF(B4="","",ROW()-2) | B4: 46237 | D4: Otro | E4: Telefónico | F4: No | G4: Sí | H4: 8.6 | I4: =IF(B4="","",IF(OR(D4="",F4="",G4=""),"Faltan datos",IF(AND(C4<>"",COUNTIF(Pacientes!$A$2:$A$46,C4)=0),"Código no registrado",IF(AND(F4="Sí",G4="Sí"),"Contradicción: resuelta y derivada","OK"))))
A5: =IF(B5="","",ROW()-2) | B5: 46237 | C5: SIM-04 | D5: Ubicación | E5: Presencial | F5: No | G5: Sí | H5: 7.3 | I5: =IF(B5="","",IF(OR(D5="",F5="",G5=""),"Faltan datos",IF(AND(C5<>"",COUNTIF(Pacientes!$A$2:$A$46,C5)=0),"Código no registrado",IF(AND(F5="Sí",G5="Sí"),"Contradicción: resuelta y derivada","OK"))))
A6: =IF(B6="","",ROW()-2) | B6: 46237 | C6: SIM-03 | D6: Información institucional | E6: WhatsApp institucional | F6: No | G6: Sí | H6: 18.7 | I6: =IF(B6="","",IF(OR(D6="",F6="",G6=""),"Faltan datos",IF(AND(C6<>"",COUNTIF(Pacientes!$A$2:$A$46,C6)=0),"Código no registrado",IF(AND(F6="Sí",G6="Sí"),"Contradicción: resuelta y derivada","OK"))))
A7: =IF(B7="","",ROW()-2) | B7: 46237 | C7: SIM-15 | D7: Horarios | E7: Presencial | F7: No | G7: Sí | H7: 10.2 | I7: =IF(B7="","",IF(OR(D7="",F7="",G7=""),"Faltan datos",IF(AND(C7<>"",COUNTIF(Pacientes!$A$2:$A$46,C7)=0),"Código no registrado",IF(AND(F7="Sí",G7="Sí"),"Contradicción: resuelta y derivada","OK"))))
A8: =IF(B8="","",ROW()-2) | B8: 46237 | C8: SIM-26 | D8: Información institucional | E8: WhatsApp institucional | F8: Sí | G8: No | H8: 8.5 | I8: =IF(B8="","",IF(OR(D8="",F8="",G8=""),"Faltan datos",IF(AND(C8<>"",COUNTIF(Pacientes!$A$2:$A$46,C8)=0),"Código no registrado",IF(AND(F8="Sí",G8="Sí"),"Contradicción: resuelta y derivada","OK"))))
A9: =IF(B9="","",ROW()-2) | B9: 46237 | C9: SIM-22 | D9: Ubicación | E9: Telefónico | F9: No | G9: Sí | H9: 16 | I9: =IF(B9="","",IF(OR(D9="",F9="",G9=""),"Faltan datos",IF(AND(C9<>"",COUNTIF(Pacientes!$A$2:$A$46,C9)=0),"Código no registrado",IF(AND(F9="Sí",G9="Sí"),"Contradicción: resuelta y derivada","OK"))))
A10: =IF(B10="","",ROW()-2) | B10: 46237 | C10: SIM-06 | D10: Ubicación | E10: Presencial | F10: Sí | G10: No | H10: 15.3 | I10: =IF(B10="","",IF(OR(D10="",F10="",G10=""),"Faltan datos",IF(AND(C10<>"",COUNTIF(Pacientes!$A$2:$A$46,C10)=0),"Código no registrado",IF(AND(F10="Sí",G10="Sí"),"Contradicción: resuelta y derivada","OK"))))
A11: =IF(B11="","",ROW()-2) | B11: 46237 | C11: SIM-29 | D11: Citas | E11: Presencial | F11: Sí | G11: No | H11: 10.3 | I11: =IF(B11="","",IF(OR(D11="",F11="",G11=""),"Faltan datos",IF(AND(C11<>"",COUNTIF(Pacientes!$A$2:$A$46,C11)=0),"Código no registrado",IF(AND(F11="Sí",G11="Sí"),"Contradicción: resuelta y derivada","OK"))))
A12: =IF(B12="","",ROW()-2) | B12: 46239 | C12: SIM-05 | D12: Requisitos | E12: Presencial | F12: No | G12: Sí | H12: 9.6 | I12: =IF(B12="","",IF(OR(D12="",F12="",G12=""),"Faltan datos",IF(AND(C12<>"",COUNTIF(Pacientes!$A$2:$A$46,C12)=0),"Código no registrado",IF(AND(F12="Sí",G12="Sí"),"Contradicción: resuelta y derivada","OK"))))
A13: =IF(B13="","",ROW()-2) | B13: 46239 | C13: SIM-26 | D13: Citas | E13: Telefónico | F13: Sí | G13: No | H13: 19.5 | I13: =IF(B13="","",IF(OR(D13="",F13="",G13=""),"Faltan datos",IF(AND(C13<>"",COUNTIF(Pacientes!$A$2:$A$46,C13)=0),"Código no registrado",IF(AND(F13="Sí",G13="Sí"),"Contradicción: resuelta y derivada","OK"))))
A14: =IF(B14="","",ROW()-2) | B14: 46239 | C14: SIM-23 | D14: Citas | E14: WhatsApp institucional | F14: Sí | G14: No | H14: 11.8 | I14: =IF(B14="","",IF(OR(D14="",F14="",G14=""),"Faltan datos",IF(AND(C14<>"",COUNTIF(Pacientes!$A$2:$A$46,C14)=0),"Código no registrado",IF(AND(F14="Sí",G14="Sí"),"Contradicción: resuelta y derivada","OK"))))
A15: =IF(B15="","",ROW()-2) | B15: 46239 | C15: SIM-20 | D15: Otro | E15: Telefónico | F15: Sí | G15: No | H15: 12.7 | I15: =IF(B15="","",IF(OR(D15="",F15="",G15=""),"Faltan datos",IF(AND(C15<>"",COUNTIF(Pacientes!$A$2:$A$46,C15)=0),"Código no registrado",IF(AND(F15="Sí",G15="Sí"),"Contradicción: resuelta y derivada","OK"))))
A16: =IF(B16="","",ROW()-2) | B16: 46239 | D16: Seguimiento administrativo | E16: Telefónico | F16: Sí | G16: No | H16: 9.9 | I16: =IF(B16="","",IF(OR(D16="",F16="",G16=""),"Faltan datos",IF(AND(C16<>"",COUNTIF(Pacientes!$A$2:$A$46,C16)=0),"Código no registrado",IF(AND(F16="Sí",G16="Sí"),"Contradicción: resuelta y derivada","OK"))))
A17: =IF(B17="","",ROW()-2) | B17: 46239 | C17: SIM-12 | D17: Horarios | E17: Telefónico | F17: No | G17: No | H17: 10.3 | I17: =IF(B17="","",IF(OR(D17="",F17="",G17=""),"Faltan datos",IF(AND(C17<>"",COUNTIF(Pacientes!$A$2:$A$46,C17)=0),"Código no registrado",IF(AND(F17="Sí",G17="Sí"),"Contradicción: resuelta y derivada","OK"))))
A18: =IF(B18="","",ROW()-2) | B18: 46239 | C18: SIM-05 | D18: Ubicación | E18: WhatsApp institucional | F18: No | G18: Sí | H18: 14.6 | I18: =IF(B18="","",IF(OR(D18="",F18="",G18=""),"Faltan datos",IF(AND(C18<>"",COUNTIF(Pacientes!$A$2:$A$46,C18)=0),"Código no registrado",IF(AND(F18="Sí",G18="Sí"),"Contradicción: resuelta y derivada","OK"))))
A19: =IF(B19="","",ROW()-2) | B19: 46239 | C19: SIM-28 | D19: Citas | E19: Presencial | F19: Sí | G19: No | H19: 17 | I19: =IF(B19="","",IF(OR(D19="",F19="",G19=""),"Faltan datos",IF(AND(C19<>"",COUNTIF(Pacientes!$A$2:$A$46,C19)=0),"Código no registrado",IF(AND(F19="Sí",G19="Sí"),"Contradicción: resuelta y derivada","OK"))))
A20: =IF(B20="","",ROW()-2) | B20: 46239 | D20: Información institucional | E20: WhatsApp institucional | F20: Sí | G20: No | H20: 14.6 | I20: =IF(B20="","",IF(OR(D20="",F20="",G20=""),"Faltan datos",IF(AND(C20<>"",COUNTIF(Pacientes!$A$2:$A$46,C20)=0),"Código no registrado",IF(AND(F20="Sí",G20="Sí"),"Contradicción: resuelta y derivada","OK"))))
A21: =IF(B21="","",ROW()-2) | B21: 46241 | C21: SIM-10 | D21: Otro | E21: Presencial | F21: No | G21: No | H21: 14.2 | I21: =IF(B21="","",IF(OR(D21="",F21="",G21=""),"Faltan datos",IF(AND(C21<>"",COUNTIF(Pacientes!$A$2:$A$46,C21)=0),"Código no registrado",IF(AND(F21="Sí",G21="Sí"),"Contradicción: resuelta y derivada","OK"))))
A22: =IF(B22="","",ROW()-2) | B22: 46241 | C22: SIM-11 | D22: Requisitos | E22: Telefónico | F22: No | G22: Sí | H22: 6.4 | I22: =IF(B22="","",IF(OR(D22="",F22="",G22=""),"Faltan datos",IF(AND(C22<>"",COUNTIF(Pacientes!$A$2:$A$46,C22)=0),"Código no registrado",IF(AND(F22="Sí",G22="Sí"),"Contradicción: resuelta y derivada","OK"))))
A23: =IF(B23="","",ROW()-2) | B23: 46241 | C23: SIM-25 | D23: Citas | E23: Presencial | F23: No | G23: Sí | H23: 19.5 | I23: =IF(B23="","",IF(OR(D23="",F23="",G23=""),"Faltan datos",IF(AND(C23<>"",COUNTIF(Pacientes!$A$2:$A$46,C23)=0),"Código no registrado",IF(AND(F23="Sí",G23="Sí"),"Contradicción: resuelta y derivada","OK"))))
A24: =IF(B24="","",ROW()-2) | B24: 46241 | D24: Requisitos | E24: Presencial | F24: Sí | G24: No | H24: 15.8 | I24: =IF(B24="","",IF(OR(D24="",F24="",G24=""),"Faltan datos",IF(AND(C24<>"",COUNTIF(Pacientes!$A$2:$A$46,C24)=0),"Código no registrado",IF(AND(F24="Sí",G24="Sí"),"Contradicción: resuelta y derivada","OK"))))
A25: =IF(B25="","",ROW()-2) | B25: 46241 | C25: SIM-24 | D25: Otro | E25: Presencial | F25: Sí | G25: No | H25: 13 | I25: =IF(B25="","",IF(OR(D25="",F25="",G25=""),"Faltan datos",IF(AND(C25<>"",COUNTIF(Pacientes!$A$2:$A$46,C25)=0),"Código no registrado",IF(AND(F25="Sí",G25="Sí"),"Contradicción: resuelta y derivada","OK"))))
A26: =IF(B26="","",ROW()-2) | B26: 46241 | C26: SIM-12 | D26: Citas | E26: WhatsApp institucional | F26: Sí | G26: No | H26: 19.2 | I26: =IF(B26="","",IF(OR(D26="",F26="",G26=""),"Faltan datos",IF(AND(C26<>"",COUNTIF(Pacientes!$A$2:$A$46,C26)=0),"Código no registrado",IF(AND(F26="Sí",G26="Sí"),"Contradicción: resuelta y derivada","OK"))))
A27: =IF(B27="","",ROW()-2) | B27: 46241 | D27: Citas | E27: Presencial | F27: Sí | G27: No | H27: 13.2 | I27: =IF(B27="","",IF(OR(D27="",F27="",G27=""),"Faltan datos",IF(AND(C27<>"",COUNTIF(Pacientes!$A$2:$A$46,C27)=0),"Código no registrado",IF(AND(F27="Sí",G27="Sí"),"Contradicción: resuelta y derivada","OK"))))
